2023-06-09 19:48:01,984 INFO Watching for file changes with StatReloader 668 
2023-06-09 20:01:37,742 INFO Watching for file changes with StatReloader 668 
2023-06-09 22:47:37,347 INFO Watching for file changes with StatReloader 668 
2023-06-09 22:50:10,364 ERROR Internal Server Error: /test 241 
Traceback (most recent call last):
  File "C:\Python311\Lib\site-packages\django\db\backends\utils.py", line 89, in _execute
    return self.cursor.execute(sql, params)
           ^^^^^^^^^^^^^^^^^^^^^^^^^^^^^^^^
psycopg2.errors.UndefinedColumn: column student.created_at does not exist
LINE 1: ...ent"."id", "student"."name", "student"."address", "student"....
                                                             ^


The above exception was the direct cause of the following exception:

Traceback (most recent call last):
  File "E:\New api\newpro\newapp\views.py", line 22, in get
    for student in students:
  File "C:\Python311\Lib\site-packages\django\db\models\query.py", line 398, in __iter__
    self._fetch_all()
  File "C:\Python311\Lib\site-packages\django\db\models\query.py", line 1881, in _fetch_all
    self._result_cache = list(self._iterable_class(self))
                         ^^^^^^^^^^^^^^^^^^^^^^^^^^^^^^^^
  File "C:\Python311\Lib\site-packages\django\db\models\query.py", line 91, in __iter__
    results = compiler.execute_sql(
              ^^^^^^^^^^^^^^^^^^^^^
  File "C:\Python311\Lib\site-packages\django\db\models\sql\compiler.py", line 1560, in execute_sql
    cursor.execute(sql, params)
  File "C:\Python311\Lib\site-packages\django\db\backends\utils.py", line 102, in execute
    return super().execute(sql, params)
           ^^^^^^^^^^^^^^^^^^^^^^^^^^^^
  File "C:\Python311\Lib\site-packages\django\db\backends\utils.py", line 67, in execute
    return self._execute_with_wrappers(
           ^^^^^^^^^^^^^^^^^^^^^^^^^^^^
  File "C:\Python311\Lib\site-packages\django\db\backends\utils.py", line 80, in _execute_with_wrappers
    return executor(sql, params, many, context)
           ^^^^^^^^^^^^^^^^^^^^^^^^^^^^^^^^^^^^
  File "C:\Python311\Lib\site-packages\django\db\backends\utils.py", line 84, in _execute
    with self.db.wrap_database_errors:
  File "C:\Python311\Lib\site-packages\django\db\utils.py", line 91, in __exit__
    raise dj_exc_value.with_traceback(traceback) from exc_value
  File "C:\Python311\Lib\site-packages\django\db\backends\utils.py", line 89, in _execute
    return self.cursor.execute(sql, params)
           ^^^^^^^^^^^^^^^^^^^^^^^^^^^^^^^^
django.db.utils.ProgrammingError: column student.created_at does not exist
LINE 1: ...ent"."id", "student"."name", "student"."address", "student"....
                                                             ^


During handling of the above exception, another exception occurred:

Traceback (most recent call last):
  File "C:\Python311\Lib\site-packages\django\core\handlers\exception.py", line 55, in inner
    response = get_response(request)
               ^^^^^^^^^^^^^^^^^^^^^
  File "C:\Python311\Lib\site-packages\django\core\handlers\base.py", line 197, in _get_response
    response = wrapped_callback(request, *callback_args, **callback_kwargs)
               ^^^^^^^^^^^^^^^^^^^^^^^^^^^^^^^^^^^^^^^^^^^^^^^^^^^^^^^^^^^^
  File "C:\Python311\Lib\site-packages\django\views\decorators\csrf.py", line 56, in wrapper_view
    return view_func(*args, **kwargs)
           ^^^^^^^^^^^^^^^^^^^^^^^^^^
  File "C:\Python311\Lib\site-packages\django\views\generic\base.py", line 104, in view
    return self.dispatch(request, *args, **kwargs)
           ^^^^^^^^^^^^^^^^^^^^^^^^^^^^^^^^^^^^^^^
  File "C:\Python311\Lib\site-packages\rest_framework\views.py", line 509, in dispatch
    response = self.handle_exception(exc)
               ^^^^^^^^^^^^^^^^^^^^^^^^^^
  File "C:\Python311\Lib\site-packages\rest_framework\views.py", line 469, in handle_exception
    self.raise_uncaught_exception(exc)
  File "C:\Python311\Lib\site-packages\rest_framework\views.py", line 480, in raise_uncaught_exception
    raise exc
  File "C:\Python311\Lib\site-packages\rest_framework\views.py", line 506, in dispatch
    response = handler(request, *args, **kwargs)
               ^^^^^^^^^^^^^^^^^^^^^^^^^^^^^^^^^
  File "E:\New api\newpro\newapp\views.py", line 35, in get
    logger.info(str(e), exe_info=True)
  File "C:\Python311\Lib\logging\__init__.py", line 1489, in info
    self._log(INFO, msg, args, **kwargs)
TypeError: Logger._log() got an unexpected keyword argument 'exe_info'
2023-06-09 22:50:10,375 ERROR "GET /test HTTP/1.1" 500 151622 212 
2023-06-09 22:50:19,965 INFO "POST /test HTTP/1.1" 202 102 212 
2023-06-09 22:57:50,157 INFO E:\New api\newpro\newapp\models.py changed, reloading. 266 
2023-06-09 22:57:51,507 INFO Watching for file changes with StatReloader 668 
2023-06-09 22:57:59,146 INFO "GET /test HTTP/1.1" 202 226 212 
2023-06-09 23:23:35,772 INFO E:\New api\newpro\newapp\views.py changed, reloading. 266 
2023-06-09 23:23:37,059 INFO Watching for file changes with StatReloader 668 
2023-06-09 23:25:20,890 INFO E:\New api\newpro\newapp\views.py changed, reloading. 266 
2023-06-09 23:25:22,120 INFO Watching for file changes with StatReloader 668 
2023-06-09 23:30:03,799 INFO E:\New api\newpro\newapp\views.py changed, reloading. 266 
2023-06-09 23:30:05,171 INFO Watching for file changes with StatReloader 668 
2023-06-09 23:30:11,525 INFO E:\New api\newpro\newapp\models.py changed, reloading. 266 
2023-06-09 23:30:12,809 INFO Watching for file changes with StatReloader 668 
2023-06-09 23:35:12,911 INFO E:\New api\newpro\newapp\views.py changed, reloading. 266 
2023-06-09 23:35:14,166 INFO Watching for file changes with StatReloader 668 
2023-06-09 23:37:11,780 INFO Watching for file changes with StatReloader 668 
2023-06-09 23:37:53,943 INFO E:\New api\newpro\newapp\views.py changed, reloading. 266 
2023-06-09 23:37:55,182 INFO Watching for file changes with StatReloader 668 
2023-06-09 23:38:02,719 INFO "GET /test HTTP/1.1" 202 96 212 
2023-06-09 23:39:18,325 INFO E:\New api\newpro\newapp\views.py changed, reloading. 266 
2023-06-09 23:39:19,566 INFO Watching for file changes with StatReloader 668 
2023-06-09 23:39:24,108 INFO "GET /test HTTP/1.1" 202 163 212 
2023-06-09 23:40:29,605 INFO E:\New api\newpro\newapp\views.py changed, reloading. 266 
2023-06-09 23:40:30,865 INFO Watching for file changes with StatReloader 668 
2023-06-09 23:40:35,794 INFO "GET /test HTTP/1.1" 202 226 212 
2023-06-10 11:41:03,786 INFO Watching for file changes with StatReloader 668 
2023-06-10 11:44:57,493 INFO "GET /test HTTP/1.1" 202 226 212 
2023-06-10 12:02:13,250 INFO E:\New api\newpro\newapp\serializers.py changed, reloading. 266 
2023-06-10 12:02:14,504 INFO Watching for file changes with StatReloader 668 
2023-06-10 12:04:45,407 INFO "POST /test HTTP/1.1" 202 102 212 
2023-06-10 12:07:33,991 INFO E:\New api\newpro\newapp\views.py changed, reloading. 266 
2023-06-10 12:07:35,415 INFO Watching for file changes with StatReloader 668 
2023-06-10 12:07:39,794 WARNING Bad Request: /test 241 
2023-06-10 12:07:39,795 WARNING "POST /test HTTP/1.1" 400 82 212 
2023-06-10 12:12:53,358 INFO E:\New api\newpro\newapp\views.py changed, reloading. 266 
2023-06-10 12:12:54,678 INFO Watching for file changes with StatReloader 668 
2023-06-10 12:15:20,978 INFO E:\New api\newpro\newapp\views.py changed, reloading. 266 
2023-06-10 12:15:22,273 INFO Watching for file changes with StatReloader 668 
2023-06-10 12:18:37,377 INFO E:\New api\newpro\newapp\views.py changed, reloading. 266 
2023-06-10 12:18:38,623 INFO Watching for file changes with StatReloader 668 
2023-06-10 12:20:58,504 INFO E:\New api\newpro\newapp\views.py changed, reloading. 266 
2023-06-10 12:20:59,776 INFO Watching for file changes with StatReloader 668 
2023-06-10 12:22:40,155 INFO E:\New api\newpro\newapp\views.py changed, reloading. 266 
2023-06-10 12:22:41,398 INFO Watching for file changes with StatReloader 668 
2023-06-10 12:22:46,799 WARNING Bad Request: /test 241 
2023-06-10 12:22:46,799 WARNING "POST /test HTTP/1.1" 400 82 212 
2023-06-10 12:23:35,269 WARNING Bad Request: /test 241 
2023-06-10 12:23:35,270 WARNING "POST /test HTTP/1.1" 400 82 212 
2023-06-10 12:24:17,568 INFO E:\New api\newpro\newapp\serializers.py changed, reloading. 266 
2023-06-10 12:24:19,073 INFO Watching for file changes with StatReloader 668 
2023-06-10 12:24:21,826 INFO E:\New api\newpro\newapp\models.py changed, reloading. 266 
2023-06-10 12:24:23,942 INFO Watching for file changes with StatReloader 668 
2023-06-10 12:24:27,744 INFO E:\New api\newpro\newapp\views.py changed, reloading. 266 
2023-06-10 12:24:29,061 INFO Watching for file changes with StatReloader 668 
2023-06-10 12:24:51,440 INFO Watching for file changes with StatReloader 668 
2023-06-10 12:24:58,702 WARNING Bad Request: /test 241 
2023-06-10 12:24:58,702 WARNING "POST /test HTTP/1.1" 400 82 212 
2023-06-10 12:26:06,899 WARNING Bad Request: /test 241 
2023-06-10 12:26:06,899 WARNING "POST /test HTTP/1.1" 400 82 212 
2023-06-10 12:26:10,555 WARNING Bad Request: /test 241 
2023-06-10 12:26:10,556 WARNING "POST /test HTTP/1.1" 400 82 212 
2023-06-10 12:26:32,987 ERROR Internal Server Error: /test 241 
Traceback (most recent call last):
  File "C:\Python311\Lib\site-packages\django\db\backends\utils.py", line 89, in _execute
    return self.cursor.execute(sql, params)
           ^^^^^^^^^^^^^^^^^^^^^^^^^^^^^^^^
psycopg2.errors.UniqueViolation: duplicate key value violates unique constraint "student_pkey"
DETAIL:  Key (id)=(2) already exists.


The above exception was the direct cause of the following exception:

Traceback (most recent call last):
  File "C:\Python311\Lib\site-packages\django\core\handlers\exception.py", line 55, in inner
    response = get_response(request)
               ^^^^^^^^^^^^^^^^^^^^^
  File "C:\Python311\Lib\site-packages\django\core\handlers\base.py", line 197, in _get_response
    response = wrapped_callback(request, *callback_args, **callback_kwargs)
               ^^^^^^^^^^^^^^^^^^^^^^^^^^^^^^^^^^^^^^^^^^^^^^^^^^^^^^^^^^^^
  File "C:\Python311\Lib\site-packages\django\views\decorators\csrf.py", line 56, in wrapper_view
    return view_func(*args, **kwargs)
           ^^^^^^^^^^^^^^^^^^^^^^^^^^
  File "C:\Python311\Lib\site-packages\django\views\generic\base.py", line 104, in view
    return self.dispatch(request, *args, **kwargs)
           ^^^^^^^^^^^^^^^^^^^^^^^^^^^^^^^^^^^^^^^
  File "C:\Python311\Lib\site-packages\rest_framework\views.py", line 509, in dispatch
    response = self.handle_exception(exc)
               ^^^^^^^^^^^^^^^^^^^^^^^^^^
  File "C:\Python311\Lib\site-packages\rest_framework\views.py", line 469, in handle_exception
    self.raise_uncaught_exception(exc)
  File "C:\Python311\Lib\site-packages\rest_framework\views.py", line 480, in raise_uncaught_exception
    raise exc
  File "C:\Python311\Lib\site-packages\rest_framework\views.py", line 506, in dispatch
    response = handler(request, *args, **kwargs)
               ^^^^^^^^^^^^^^^^^^^^^^^^^^^^^^^^^
  File "E:\New api\newpro\newapp\views.py", line 47, in post
    serializer.save()
  File "C:\Python311\Lib\site-packages\rest_framework\serializers.py", line 212, in save
    self.instance = self.create(validated_data)
                    ^^^^^^^^^^^^^^^^^^^^^^^^^^^
  File "E:\New api\newpro\newapp\serializers.py", line 10, in create
    return Student.objects.create(**validated_data)
         ^^^^^^^^^^^^^^^^^^^^^^^^^^^^^^^^^^^^^^^^
  File "C:\Python311\Lib\site-packages\django\db\models\manager.py", line 87, in manager_method
    return getattr(self.get_queryset(), name)(*args, **kwargs)
           ^^^^^^^^^^^^^^^^^^^^^^^^^^^^^^^^^^^^^^^^^^^^^^^^^^^
  File "C:\Python311\Lib\site-packages\django\db\models\query.py", line 658, in create
    obj.save(force_insert=True, using=self.db)
  File "C:\Python311\Lib\site-packages\django\db\models\base.py", line 814, in save
    self.save_base(
  File "C:\Python311\Lib\site-packages\django\db\models\base.py", line 877, in save_base
    updated = self._save_table(
              ^^^^^^^^^^^^^^^^^
  File "C:\Python311\Lib\site-packages\django\db\models\base.py", line 1020, in _save_table
    results = self._do_insert(
              ^^^^^^^^^^^^^^^^
  File "C:\Python311\Lib\site-packages\django\db\models\base.py", line 1061, in _do_insert
    return manager._insert(
           ^^^^^^^^^^^^^^^^
  File "C:\Python311\Lib\site-packages\django\db\models\manager.py", line 87, in manager_method
    return getattr(self.get_queryset(), name)(*args, **kwargs)
           ^^^^^^^^^^^^^^^^^^^^^^^^^^^^^^^^^^^^^^^^^^^^^^^^^^^
  File "C:\Python311\Lib\site-packages\django\db\models\query.py", line 1805, in _insert
    return query.get_compiler(using=using).execute_sql(returning_fields)
           ^^^^^^^^^^^^^^^^^^^^^^^^^^^^^^^^^^^^^^^^^^^^^^^^^^^^^^^^^^^^^
  File "C:\Python311\Lib\site-packages\django\db\models\sql\compiler.py", line 1820, in execute_sql
    cursor.execute(sql, params)
  File "C:\Python311\Lib\site-packages\django\db\backends\utils.py", line 102, in execute
    return super().execute(sql, params)
           ^^^^^^^^^^^^^^^^^^^^^^^^^^^^
  File "C:\Python311\Lib\site-packages\django\db\backends\utils.py", line 67, in execute
    return self._execute_with_wrappers(
           ^^^^^^^^^^^^^^^^^^^^^^^^^^^^
  File "C:\Python311\Lib\site-packages\django\db\backends\utils.py", line 80, in _execute_with_wrappers
    return executor(sql, params, many, context)
           ^^^^^^^^^^^^^^^^^^^^^^^^^^^^^^^^^^^^
  File "C:\Python311\Lib\site-packages\django\db\backends\utils.py", line 84, in _execute
    with self.db.wrap_database_errors:
  File "C:\Python311\Lib\site-packages\django\db\utils.py", line 91, in __exit__
    raise dj_exc_value.with_traceback(traceback) from exc_value
  File "C:\Python311\Lib\site-packages\django\db\backends\utils.py", line 89, in _execute
    return self.cursor.execute(sql, params)
           ^^^^^^^^^^^^^^^^^^^^^^^^^^^^^^^^
django.db.utils.IntegrityError: duplicate key value violates unique constraint "student_pkey"
DETAIL:  Key (id)=(2) already exists.

2023-06-10 12:26:32,999 ERROR "POST /test HTTP/1.1" 500 176614 212 
2023-06-10 12:26:38,159 ERROR Internal Server Error: /test 241 
Traceback (most recent call last):
  File "C:\Python311\Lib\site-packages\django\db\backends\utils.py", line 89, in _execute
    return self.cursor.execute(sql, params)
           ^^^^^^^^^^^^^^^^^^^^^^^^^^^^^^^^
psycopg2.errors.UniqueViolation: duplicate key value violates unique constraint "student_pkey"
DETAIL:  Key (id)=(3) already exists.


The above exception was the direct cause of the following exception:

Traceback (most recent call last):
  File "C:\Python311\Lib\site-packages\django\core\handlers\exception.py", line 55, in inner
    response = get_response(request)
               ^^^^^^^^^^^^^^^^^^^^^
  File "C:\Python311\Lib\site-packages\django\core\handlers\base.py", line 197, in _get_response
    response = wrapped_callback(request, *callback_args, **callback_kwargs)
               ^^^^^^^^^^^^^^^^^^^^^^^^^^^^^^^^^^^^^^^^^^^^^^^^^^^^^^^^^^^^
  File "C:\Python311\Lib\site-packages\django\views\decorators\csrf.py", line 56, in wrapper_view
    return view_func(*args, **kwargs)
           ^^^^^^^^^^^^^^^^^^^^^^^^^^
  File "C:\Python311\Lib\site-packages\django\views\generic\base.py", line 104, in view
    return self.dispatch(request, *args, **kwargs)
           ^^^^^^^^^^^^^^^^^^^^^^^^^^^^^^^^^^^^^^^
  File "C:\Python311\Lib\site-packages\rest_framework\views.py", line 509, in dispatch
    response = self.handle_exception(exc)
               ^^^^^^^^^^^^^^^^^^^^^^^^^^
  File "C:\Python311\Lib\site-packages\rest_framework\views.py", line 469, in handle_exception
    self.raise_uncaught_exception(exc)
  File "C:\Python311\Lib\site-packages\rest_framework\views.py", line 480, in raise_uncaught_exception
    raise exc
  File "C:\Python311\Lib\site-packages\rest_framework\views.py", line 506, in dispatch
    response = handler(request, *args, **kwargs)
               ^^^^^^^^^^^^^^^^^^^^^^^^^^^^^^^^^
  File "E:\New api\newpro\newapp\views.py", line 47, in post
    serializer.save()
  File "C:\Python311\Lib\site-packages\rest_framework\serializers.py", line 212, in save
    self.instance = self.create(validated_data)
                    ^^^^^^^^^^^^^^^^^^^^^^^^^^^
  File "E:\New api\newpro\newapp\serializers.py", line 10, in create
    return Student.objects.create(**validated_data)
         ^^^^^^^^^^^^^^^^^^^^^^^^^^^^^^^^^^^^^^^^
  File "C:\Python311\Lib\site-packages\django\db\models\manager.py", line 87, in manager_method
    return getattr(self.get_queryset(), name)(*args, **kwargs)
           ^^^^^^^^^^^^^^^^^^^^^^^^^^^^^^^^^^^^^^^^^^^^^^^^^^^
  File "C:\Python311\Lib\site-packages\django\db\models\query.py", line 658, in create
    obj.save(force_insert=True, using=self.db)
  File "C:\Python311\Lib\site-packages\django\db\models\base.py", line 814, in save
    self.save_base(
  File "C:\Python311\Lib\site-packages\django\db\models\base.py", line 877, in save_base
    updated = self._save_table(
              ^^^^^^^^^^^^^^^^^
  File "C:\Python311\Lib\site-packages\django\db\models\base.py", line 1020, in _save_table
    results = self._do_insert(
              ^^^^^^^^^^^^^^^^
  File "C:\Python311\Lib\site-packages\django\db\models\base.py", line 1061, in _do_insert
    return manager._insert(
           ^^^^^^^^^^^^^^^^
  File "C:\Python311\Lib\site-packages\django\db\models\manager.py", line 87, in manager_method
    return getattr(self.get_queryset(), name)(*args, **kwargs)
           ^^^^^^^^^^^^^^^^^^^^^^^^^^^^^^^^^^^^^^^^^^^^^^^^^^^
  File "C:\Python311\Lib\site-packages\django\db\models\query.py", line 1805, in _insert
    return query.get_compiler(using=using).execute_sql(returning_fields)
           ^^^^^^^^^^^^^^^^^^^^^^^^^^^^^^^^^^^^^^^^^^^^^^^^^^^^^^^^^^^^^
  File "C:\Python311\Lib\site-packages\django\db\models\sql\compiler.py", line 1820, in execute_sql
    cursor.execute(sql, params)
  File "C:\Python311\Lib\site-packages\django\db\backends\utils.py", line 102, in execute
    return super().execute(sql, params)
           ^^^^^^^^^^^^^^^^^^^^^^^^^^^^
  File "C:\Python311\Lib\site-packages\django\db\backends\utils.py", line 67, in execute
    return self._execute_with_wrappers(
           ^^^^^^^^^^^^^^^^^^^^^^^^^^^^
  File "C:\Python311\Lib\site-packages\django\db\backends\utils.py", line 80, in _execute_with_wrappers
    return executor(sql, params, many, context)
           ^^^^^^^^^^^^^^^^^^^^^^^^^^^^^^^^^^^^
  File "C:\Python311\Lib\site-packages\django\db\backends\utils.py", line 84, in _execute
    with self.db.wrap_database_errors:
  File "C:\Python311\Lib\site-packages\django\db\utils.py", line 91, in __exit__
    raise dj_exc_value.with_traceback(traceback) from exc_value
  File "C:\Python311\Lib\site-packages\django\db\backends\utils.py", line 89, in _execute
    return self.cursor.execute(sql, params)
           ^^^^^^^^^^^^^^^^^^^^^^^^^^^^^^^^
django.db.utils.IntegrityError: duplicate key value violates unique constraint "student_pkey"
DETAIL:  Key (id)=(3) already exists.

2023-06-10 12:26:38,165 ERROR "POST /test HTTP/1.1" 500 176614 212 
2023-06-10 12:28:39,854 INFO "POST /test HTTP/1.1" 200 33 212 
2023-06-10 12:29:45,609 INFO "POST /test HTTP/1.1" 200 33 212 
2023-06-10 12:30:38,765 INFO "POST /test HTTP/1.1" 200 33 212 
2023-06-10 12:39:02,000 INFO "GET /test HTTP/1.1" 202 411 212 
2023-06-10 12:43:57,772 INFO E:\New api\newpro\newapp\serializers.py changed, reloading. 266 
2023-06-10 12:43:59,124 INFO Watching for file changes with StatReloader 668 
2023-06-10 12:44:48,569 ERROR Internal Server Error: /test 241 
Traceback (most recent call last):
  File "C:\Python311\Lib\site-packages\django\core\handlers\exception.py", line 55, in inner
    response = get_response(request)
               ^^^^^^^^^^^^^^^^^^^^^
  File "C:\Python311\Lib\site-packages\django\core\handlers\base.py", line 197, in _get_response
    response = wrapped_callback(request, *callback_args, **callback_kwargs)
               ^^^^^^^^^^^^^^^^^^^^^^^^^^^^^^^^^^^^^^^^^^^^^^^^^^^^^^^^^^^^
  File "C:\Python311\Lib\site-packages\django\views\decorators\csrf.py", line 56, in wrapper_view
    return view_func(*args, **kwargs)
           ^^^^^^^^^^^^^^^^^^^^^^^^^^
  File "C:\Python311\Lib\site-packages\django\views\generic\base.py", line 104, in view
    return self.dispatch(request, *args, **kwargs)
           ^^^^^^^^^^^^^^^^^^^^^^^^^^^^^^^^^^^^^^^
  File "C:\Python311\Lib\site-packages\rest_framework\views.py", line 509, in dispatch
    response = self.handle_exception(exc)
               ^^^^^^^^^^^^^^^^^^^^^^^^^^
  File "C:\Python311\Lib\site-packages\rest_framework\views.py", line 469, in handle_exception
    self.raise_uncaught_exception(exc)
  File "C:\Python311\Lib\site-packages\rest_framework\views.py", line 480, in raise_uncaught_exception
    raise exc
  File "C:\Python311\Lib\site-packages\rest_framework\views.py", line 506, in dispatch
    response = handler(request, *args, **kwargs)
               ^^^^^^^^^^^^^^^^^^^^^^^^^^^^^^^^^
  File "E:\New api\newpro\newapp\views.py", line 47, in post
    serializer.save()
  File "C:\Python311\Lib\site-packages\rest_framework\serializers.py", line 212, in save
    self.instance = self.create(validated_data)
                    ^^^^^^^^^^^^^^^^^^^^^^^^^^^
  File "E:\New api\newpro\newapp\serializers.py", line 10, in create
    return Student.objects.create(**validated_data)
         ^^^^^^^^^^^^^^^^^^^^^^^^^^^^^^^^^^^^^^^^
  File "C:\Python311\Lib\site-packages\django\db\models\manager.py", line 87, in manager_method
    return getattr(self.get_queryset(), name)(*args, **kwargs)
           ^^^^^^^^^^^^^^^^^^^^^^^^^^^^^^^^^^^^^^^^^^^^^^^^^^^
  File "C:\Python311\Lib\site-packages\django\db\models\query.py", line 656, in create
    obj = self.model(**kwargs)
          ^^^^^^^^^^^^^^^^^^^^
  File "C:\Python311\Lib\site-packages\django\db\models\base.py", line 567, in __init__
    raise TypeError(
TypeError: Student() got unexpected keyword arguments: 'age'
2023-06-10 12:44:48,577 ERROR "POST /test HTTP/1.1" 500 113208 212 
2023-06-10 12:56:19,519 INFO E:\New api\newpro\newapp\models.py changed, reloading. 266 
2023-06-10 12:56:20,887 INFO Watching for file changes with StatReloader 668 
2023-06-10 12:57:15,764 ERROR Internal Server Error: /test 241 
Traceback (most recent call last):
  File "C:\Python311\Lib\site-packages\django\db\backends\utils.py", line 89, in _execute
    return self.cursor.execute(sql, params)
           ^^^^^^^^^^^^^^^^^^^^^^^^^^^^^^^^
psycopg2.errors.DatatypeMismatch: column "age" is of type boolean but expression is of type integer
LINE 1: ..., "address", "age") VALUES ('Prakiti', 'Pokhara', 20) RETURN...
                                                             ^
HINT:  You will need to rewrite or cast the expression.


The above exception was the direct cause of the following exception:

Traceback (most recent call last):
  File "C:\Python311\Lib\site-packages\django\core\handlers\exception.py", line 55, in inner
    response = get_response(request)
               ^^^^^^^^^^^^^^^^^^^^^
  File "C:\Python311\Lib\site-packages\django\core\handlers\base.py", line 197, in _get_response
    response = wrapped_callback(request, *callback_args, **callback_kwargs)
               ^^^^^^^^^^^^^^^^^^^^^^^^^^^^^^^^^^^^^^^^^^^^^^^^^^^^^^^^^^^^
  File "C:\Python311\Lib\site-packages\django\views\decorators\csrf.py", line 56, in wrapper_view
    return view_func(*args, **kwargs)
           ^^^^^^^^^^^^^^^^^^^^^^^^^^
  File "C:\Python311\Lib\site-packages\django\views\generic\base.py", line 104, in view
    return self.dispatch(request, *args, **kwargs)
           ^^^^^^^^^^^^^^^^^^^^^^^^^^^^^^^^^^^^^^^
  File "C:\Python311\Lib\site-packages\rest_framework\views.py", line 509, in dispatch
    response = self.handle_exception(exc)
               ^^^^^^^^^^^^^^^^^^^^^^^^^^
  File "C:\Python311\Lib\site-packages\rest_framework\views.py", line 469, in handle_exception
    self.raise_uncaught_exception(exc)
  File "C:\Python311\Lib\site-packages\rest_framework\views.py", line 480, in raise_uncaught_exception
    raise exc
  File "C:\Python311\Lib\site-packages\rest_framework\views.py", line 506, in dispatch
    response = handler(request, *args, **kwargs)
               ^^^^^^^^^^^^^^^^^^^^^^^^^^^^^^^^^
  File "E:\New api\newpro\newapp\views.py", line 47, in post
    serializer.save()
  File "C:\Python311\Lib\site-packages\rest_framework\serializers.py", line 212, in save
    self.instance = self.create(validated_data)
                    ^^^^^^^^^^^^^^^^^^^^^^^^^^^
  File "E:\New api\newpro\newapp\serializers.py", line 10, in create
    return Student.objects.create(**validated_data)
         ^^^^^^^^^^^^^^^^^^^^^^^^^^^^^^^^^^^^^^^^
  File "C:\Python311\Lib\site-packages\django\db\models\manager.py", line 87, in manager_method
    return getattr(self.get_queryset(), name)(*args, **kwargs)
           ^^^^^^^^^^^^^^^^^^^^^^^^^^^^^^^^^^^^^^^^^^^^^^^^^^^
  File "C:\Python311\Lib\site-packages\django\db\models\query.py", line 658, in create
    obj.save(force_insert=True, using=self.db)
  File "C:\Python311\Lib\site-packages\django\db\models\base.py", line 814, in save
    self.save_base(
  File "C:\Python311\Lib\site-packages\django\db\models\base.py", line 877, in save_base
    updated = self._save_table(
              ^^^^^^^^^^^^^^^^^
  File "C:\Python311\Lib\site-packages\django\db\models\base.py", line 1020, in _save_table
    results = self._do_insert(
              ^^^^^^^^^^^^^^^^
  File "C:\Python311\Lib\site-packages\django\db\models\base.py", line 1061, in _do_insert
    return manager._insert(
           ^^^^^^^^^^^^^^^^
  File "C:\Python311\Lib\site-packages\django\db\models\manager.py", line 87, in manager_method
    return getattr(self.get_queryset(), name)(*args, **kwargs)
           ^^^^^^^^^^^^^^^^^^^^^^^^^^^^^^^^^^^^^^^^^^^^^^^^^^^
  File "C:\Python311\Lib\site-packages\django\db\models\query.py", line 1805, in _insert
    return query.get_compiler(using=using).execute_sql(returning_fields)
           ^^^^^^^^^^^^^^^^^^^^^^^^^^^^^^^^^^^^^^^^^^^^^^^^^^^^^^^^^^^^^
  File "C:\Python311\Lib\site-packages\django\db\models\sql\compiler.py", line 1820, in execute_sql
    cursor.execute(sql, params)
  File "C:\Python311\Lib\site-packages\django\db\backends\utils.py", line 102, in execute
    return super().execute(sql, params)
           ^^^^^^^^^^^^^^^^^^^^^^^^^^^^
  File "C:\Python311\Lib\site-packages\django\db\backends\utils.py", line 67, in execute
    return self._execute_with_wrappers(
           ^^^^^^^^^^^^^^^^^^^^^^^^^^^^
  File "C:\Python311\Lib\site-packages\django\db\backends\utils.py", line 80, in _execute_with_wrappers
    return executor(sql, params, many, context)
           ^^^^^^^^^^^^^^^^^^^^^^^^^^^^^^^^^^^^
  File "C:\Python311\Lib\site-packages\django\db\backends\utils.py", line 84, in _execute
    with self.db.wrap_database_errors:
  File "C:\Python311\Lib\site-packages\django\db\utils.py", line 91, in __exit__
    raise dj_exc_value.with_traceback(traceback) from exc_value
  File "C:\Python311\Lib\site-packages\django\db\backends\utils.py", line 89, in _execute
    return self.cursor.execute(sql, params)
           ^^^^^^^^^^^^^^^^^^^^^^^^^^^^^^^^
django.db.utils.ProgrammingError: column "age" is of type boolean but expression is of type integer
LINE 1: ..., "address", "age") VALUES ('Prakiti', 'Pokhara', 20) RETURN...
                                                             ^
HINT:  You will need to rewrite or cast the expression.

2023-06-10 12:57:15,780 ERROR "POST /test HTTP/1.1" 500 178725 212 
2023-06-10 13:00:23,898 INFO E:\New api\newpro\newapp\models.py changed, reloading. 266 
2023-06-10 13:00:25,348 INFO Watching for file changes with StatReloader 668 
2023-06-10 13:00:31,637 ERROR Internal Server Error: /test 241 
Traceback (most recent call last):
  File "C:\Python311\Lib\site-packages\django\db\backends\utils.py", line 89, in _execute
    return self.cursor.execute(sql, params)
           ^^^^^^^^^^^^^^^^^^^^^^^^^^^^^^^^
psycopg2.errors.DatatypeMismatch: column "age" is of type boolean but expression is of type integer
LINE 1: ..., "address", "age") VALUES ('Prakiti', 'Pokhara', 20) RETURN...
                                                             ^
HINT:  You will need to rewrite or cast the expression.


The above exception was the direct cause of the following exception:

Traceback (most recent call last):
  File "C:\Python311\Lib\site-packages\django\core\handlers\exception.py", line 55, in inner
    response = get_response(request)
               ^^^^^^^^^^^^^^^^^^^^^
  File "C:\Python311\Lib\site-packages\django\core\handlers\base.py", line 197, in _get_response
    response = wrapped_callback(request, *callback_args, **callback_kwargs)
               ^^^^^^^^^^^^^^^^^^^^^^^^^^^^^^^^^^^^^^^^^^^^^^^^^^^^^^^^^^^^
  File "C:\Python311\Lib\site-packages\django\views\decorators\csrf.py", line 56, in wrapper_view
    return view_func(*args, **kwargs)
           ^^^^^^^^^^^^^^^^^^^^^^^^^^
  File "C:\Python311\Lib\site-packages\django\views\generic\base.py", line 104, in view
    return self.dispatch(request, *args, **kwargs)
           ^^^^^^^^^^^^^^^^^^^^^^^^^^^^^^^^^^^^^^^
  File "C:\Python311\Lib\site-packages\rest_framework\views.py", line 509, in dispatch
    response = self.handle_exception(exc)
               ^^^^^^^^^^^^^^^^^^^^^^^^^^
  File "C:\Python311\Lib\site-packages\rest_framework\views.py", line 469, in handle_exception
    self.raise_uncaught_exception(exc)
  File "C:\Python311\Lib\site-packages\rest_framework\views.py", line 480, in raise_uncaught_exception
    raise exc
  File "C:\Python311\Lib\site-packages\rest_framework\views.py", line 506, in dispatch
    response = handler(request, *args, **kwargs)
               ^^^^^^^^^^^^^^^^^^^^^^^^^^^^^^^^^
  File "E:\New api\newpro\newapp\views.py", line 47, in post
    serializer.save()
  File "C:\Python311\Lib\site-packages\rest_framework\serializers.py", line 212, in save
    self.instance = self.create(validated_data)
                    ^^^^^^^^^^^^^^^^^^^^^^^^^^^
  File "E:\New api\newpro\newapp\serializers.py", line 10, in create
    return Student.objects.create(**validated_data)
         ^^^^^^^^^^^^^^^^^^^^^^^^^^^^^^^^^^^^^^^^
  File "C:\Python311\Lib\site-packages\django\db\models\manager.py", line 87, in manager_method
    return getattr(self.get_queryset(), name)(*args, **kwargs)
           ^^^^^^^^^^^^^^^^^^^^^^^^^^^^^^^^^^^^^^^^^^^^^^^^^^^
  File "C:\Python311\Lib\site-packages\django\db\models\query.py", line 658, in create
    obj.save(force_insert=True, using=self.db)
  File "C:\Python311\Lib\site-packages\django\db\models\base.py", line 814, in save
    self.save_base(
  File "C:\Python311\Lib\site-packages\django\db\models\base.py", line 877, in save_base
    updated = self._save_table(
              ^^^^^^^^^^^^^^^^^
  File "C:\Python311\Lib\site-packages\django\db\models\base.py", line 1020, in _save_table
    results = self._do_insert(
              ^^^^^^^^^^^^^^^^
  File "C:\Python311\Lib\site-packages\django\db\models\base.py", line 1061, in _do_insert
    return manager._insert(
           ^^^^^^^^^^^^^^^^
  File "C:\Python311\Lib\site-packages\django\db\models\manager.py", line 87, in manager_method
    return getattr(self.get_queryset(), name)(*args, **kwargs)
           ^^^^^^^^^^^^^^^^^^^^^^^^^^^^^^^^^^^^^^^^^^^^^^^^^^^
  File "C:\Python311\Lib\site-packages\django\db\models\query.py", line 1805, in _insert
    return query.get_compiler(using=using).execute_sql(returning_fields)
           ^^^^^^^^^^^^^^^^^^^^^^^^^^^^^^^^^^^^^^^^^^^^^^^^^^^^^^^^^^^^^
  File "C:\Python311\Lib\site-packages\django\db\models\sql\compiler.py", line 1820, in execute_sql
    cursor.execute(sql, params)
  File "C:\Python311\Lib\site-packages\django\db\backends\utils.py", line 102, in execute
    return super().execute(sql, params)
           ^^^^^^^^^^^^^^^^^^^^^^^^^^^^
  File "C:\Python311\Lib\site-packages\django\db\backends\utils.py", line 67, in execute
    return self._execute_with_wrappers(
           ^^^^^^^^^^^^^^^^^^^^^^^^^^^^
  File "C:\Python311\Lib\site-packages\django\db\backends\utils.py", line 80, in _execute_with_wrappers
    return executor(sql, params, many, context)
           ^^^^^^^^^^^^^^^^^^^^^^^^^^^^^^^^^^^^
  File "C:\Python311\Lib\site-packages\django\db\backends\utils.py", line 84, in _execute
    with self.db.wrap_database_errors:
  File "C:\Python311\Lib\site-packages\django\db\utils.py", line 91, in __exit__
    raise dj_exc_value.with_traceback(traceback) from exc_value
  File "C:\Python311\Lib\site-packages\django\db\backends\utils.py", line 89, in _execute
    return self.cursor.execute(sql, params)
           ^^^^^^^^^^^^^^^^^^^^^^^^^^^^^^^^
django.db.utils.ProgrammingError: column "age" is of type boolean but expression is of type integer
LINE 1: ..., "address", "age") VALUES ('Prakiti', 'Pokhara', 20) RETURN...
                                                             ^
HINT:  You will need to rewrite or cast the expression.

2023-06-10 13:00:31,651 ERROR "POST /test HTTP/1.1" 500 178725 212 
2023-06-10 13:01:06,276 ERROR Internal Server Error: /test 241 
Traceback (most recent call last):
  File "C:\Python311\Lib\site-packages\django\db\backends\utils.py", line 89, in _execute
    return self.cursor.execute(sql, params)
           ^^^^^^^^^^^^^^^^^^^^^^^^^^^^^^^^
psycopg2.errors.DatatypeMismatch: column "age" is of type boolean but expression is of type integer
LINE 1: ...me", "address", "age") VALUES ('Mina', 'Pokhara', 22) RETURN...
                                                             ^
HINT:  You will need to rewrite or cast the expression.


The above exception was the direct cause of the following exception:

Traceback (most recent call last):
  File "C:\Python311\Lib\site-packages\django\core\handlers\exception.py", line 55, in inner
    response = get_response(request)
               ^^^^^^^^^^^^^^^^^^^^^
  File "C:\Python311\Lib\site-packages\django\core\handlers\base.py", line 197, in _get_response
    response = wrapped_callback(request, *callback_args, **callback_kwargs)
               ^^^^^^^^^^^^^^^^^^^^^^^^^^^^^^^^^^^^^^^^^^^^^^^^^^^^^^^^^^^^
  File "C:\Python311\Lib\site-packages\django\views\decorators\csrf.py", line 56, in wrapper_view
    return view_func(*args, **kwargs)
           ^^^^^^^^^^^^^^^^^^^^^^^^^^
  File "C:\Python311\Lib\site-packages\django\views\generic\base.py", line 104, in view
    return self.dispatch(request, *args, **kwargs)
           ^^^^^^^^^^^^^^^^^^^^^^^^^^^^^^^^^^^^^^^
  File "C:\Python311\Lib\site-packages\rest_framework\views.py", line 509, in dispatch
    response = self.handle_exception(exc)
               ^^^^^^^^^^^^^^^^^^^^^^^^^^
  File "C:\Python311\Lib\site-packages\rest_framework\views.py", line 469, in handle_exception
    self.raise_uncaught_exception(exc)
  File "C:\Python311\Lib\site-packages\rest_framework\views.py", line 480, in raise_uncaught_exception
    raise exc
  File "C:\Python311\Lib\site-packages\rest_framework\views.py", line 506, in dispatch
    response = handler(request, *args, **kwargs)
               ^^^^^^^^^^^^^^^^^^^^^^^^^^^^^^^^^
  File "E:\New api\newpro\newapp\views.py", line 47, in post
    serializer.save()
  File "C:\Python311\Lib\site-packages\rest_framework\serializers.py", line 212, in save
    self.instance = self.create(validated_data)
                    ^^^^^^^^^^^^^^^^^^^^^^^^^^^
  File "E:\New api\newpro\newapp\serializers.py", line 10, in create
    return Student.objects.create(**validated_data)
         ^^^^^^^^^^^^^^^^^^^^^^^^^^^^^^^^^^^^^^^^
  File "C:\Python311\Lib\site-packages\django\db\models\manager.py", line 87, in manager_method
    return getattr(self.get_queryset(), name)(*args, **kwargs)
           ^^^^^^^^^^^^^^^^^^^^^^^^^^^^^^^^^^^^^^^^^^^^^^^^^^^
  File "C:\Python311\Lib\site-packages\django\db\models\query.py", line 658, in create
    obj.save(force_insert=True, using=self.db)
  File "C:\Python311\Lib\site-packages\django\db\models\base.py", line 814, in save
    self.save_base(
  File "C:\Python311\Lib\site-packages\django\db\models\base.py", line 877, in save_base
    updated = self._save_table(
              ^^^^^^^^^^^^^^^^^
  File "C:\Python311\Lib\site-packages\django\db\models\base.py", line 1020, in _save_table
    results = self._do_insert(
              ^^^^^^^^^^^^^^^^
  File "C:\Python311\Lib\site-packages\django\db\models\base.py", line 1061, in _do_insert
    return manager._insert(
           ^^^^^^^^^^^^^^^^
  File "C:\Python311\Lib\site-packages\django\db\models\manager.py", line 87, in manager_method
    return getattr(self.get_queryset(), name)(*args, **kwargs)
           ^^^^^^^^^^^^^^^^^^^^^^^^^^^^^^^^^^^^^^^^^^^^^^^^^^^
  File "C:\Python311\Lib\site-packages\django\db\models\query.py", line 1805, in _insert
    return query.get_compiler(using=using).execute_sql(returning_fields)
           ^^^^^^^^^^^^^^^^^^^^^^^^^^^^^^^^^^^^^^^^^^^^^^^^^^^^^^^^^^^^^
  File "C:\Python311\Lib\site-packages\django\db\models\sql\compiler.py", line 1820, in execute_sql
    cursor.execute(sql, params)
  File "C:\Python311\Lib\site-packages\django\db\backends\utils.py", line 102, in execute
    return super().execute(sql, params)
           ^^^^^^^^^^^^^^^^^^^^^^^^^^^^
  File "C:\Python311\Lib\site-packages\django\db\backends\utils.py", line 67, in execute
    return self._execute_with_wrappers(
           ^^^^^^^^^^^^^^^^^^^^^^^^^^^^
  File "C:\Python311\Lib\site-packages\django\db\backends\utils.py", line 80, in _execute_with_wrappers
    return executor(sql, params, many, context)
           ^^^^^^^^^^^^^^^^^^^^^^^^^^^^^^^^^^^^
  File "C:\Python311\Lib\site-packages\django\db\backends\utils.py", line 84, in _execute
    with self.db.wrap_database_errors:
  File "C:\Python311\Lib\site-packages\django\db\utils.py", line 91, in __exit__
    raise dj_exc_value.with_traceback(traceback) from exc_value
  File "C:\Python311\Lib\site-packages\django\db\backends\utils.py", line 89, in _execute
    return self.cursor.execute(sql, params)
           ^^^^^^^^^^^^^^^^^^^^^^^^^^^^^^^^
django.db.utils.ProgrammingError: column "age" is of type boolean but expression is of type integer
LINE 1: ...me", "address", "age") VALUES ('Mina', 'Pokhara', 22) RETURN...
                                                             ^
HINT:  You will need to rewrite or cast the expression.

2023-06-10 13:01:06,281 ERROR "POST /test HTTP/1.1" 500 178730 212 
2023-06-10 13:04:01,007 INFO "GET /test HTTP/1.1" 202 360 212 
2023-06-10 13:08:29,061 INFO E:\New api\newpro\newapp\serializers.py changed, reloading. 266 
2023-06-10 13:08:30,348 INFO Watching for file changes with StatReloader 668 
2023-06-10 14:03:53,441 INFO E:\New api\newpro\newapp\serializers.py changed, reloading. 266 
2023-06-10 14:03:55,045 INFO Watching for file changes with StatReloader 668 
2023-06-10 14:04:03,022 INFO "GET /test HTTP/1.1" 202 378 212 
2023-06-10 14:04:23,144 INFO "POST /test HTTP/1.1" 200 33 212 
2023-06-10 14:04:48,293 INFO "GET /test HTTP/1.1" 202 429 212 
2023-06-10 14:20:21,347 INFO E:\New api\newpro\newapp\serializers.py changed, reloading. 266 
2023-06-10 14:20:22,692 INFO Watching for file changes with StatReloader 668 
2023-06-10 14:25:13,526 INFO E:\New api\newpro\newapp\serializers.py changed, reloading. 266 
2023-06-10 14:25:14,875 INFO Watching for file changes with StatReloader 668 
2023-06-10 14:25:34,776 INFO "POST /test HTTP/1.1" 200 33 212 
2023-06-10 14:30:49,256 INFO E:\New api\newpro\newapp\serializers.py changed, reloading. 266 
2023-06-10 14:30:50,835 INFO Watching for file changes with StatReloader 668 
2023-06-10 14:31:02,279 INFO "POST /test HTTP/1.1" 200 33 212 
2023-06-10 14:33:17,429 INFO E:\New api\newpro\newapp\serializers.py changed, reloading. 266 
2023-06-10 14:33:18,761 INFO Watching for file changes with StatReloader 668 
2023-06-10 14:35:39,268 INFO "POST /test HTTP/1.1" 200 33 212 
2023-06-10 14:36:39,208 INFO E:\New api\newpro\newapp\serializers.py changed, reloading. 266 
2023-06-10 14:36:40,537 INFO Watching for file changes with StatReloader 668 
2023-06-10 14:39:35,064 INFO E:\New api\newpro\newapp\serializers.py changed, reloading. 266 
2023-06-10 14:39:36,377 INFO Watching for file changes with StatReloader 668 
2023-06-10 14:39:46,733 INFO "POST /test HTTP/1.1" 200 33 212 
2023-06-10 15:10:04,627 INFO E:\New api\newpro\newapp\views.py changed, reloading. 266 
2023-06-10 15:10:05,964 INFO Watching for file changes with StatReloader 668 
2023-06-10 15:10:19,251 INFO "POST /test HTTP/1.1" 200 46 212 
2023-06-10 15:12:01,402 INFO E:\New api\newpro\newapp\views.py changed, reloading. 266 
2023-06-10 15:12:02,713 INFO Watching for file changes with StatReloader 668 
2023-06-10 15:12:30,584 INFO E:\New api\newpro\newapp\serializers.py changed, reloading. 266 
2023-06-10 15:12:31,850 INFO Watching for file changes with StatReloader 668 
2023-06-10 15:22:27,642 INFO E:\New api\newpro\newapp\serializers.py changed, reloading. 266 
2023-06-10 15:22:28,889 INFO Watching for file changes with StatReloader 668 
2023-06-10 15:23:02,453 INFO "POST /test HTTP/1.1" 200 46 212 
2023-06-10 15:23:54,168 INFO E:\New api\newpro\newapp\serializers.py changed, reloading. 266 
2023-06-10 15:23:55,464 INFO Watching for file changes with StatReloader 668 
2023-06-10 15:24:05,624 INFO "POST /test HTTP/1.1" 200 46 212 
2023-06-10 15:27:38,200 INFO E:\New api\newpro\newapp\serializers.py changed, reloading. 266 
2023-06-10 15:27:39,541 INFO Watching for file changes with StatReloader 668 
2023-06-10 15:27:56,314 INFO "POST /test HTTP/1.1" 200 46 212 
2023-06-10 15:28:59,307 INFO E:\New api\newpro\newapp\serializers.py changed, reloading. 266 
2023-06-10 15:29:00,644 INFO Watching for file changes with StatReloader 668 
2023-06-10 15:29:09,488 WARNING Not Found: /test 241 
2023-06-10 15:29:09,489 WARNING "POST /test HTTP/1.1" 404 118 212 
2023-06-10 15:30:26,752 INFO "POST /test HTTP/1.1" 200 46 212 
2023-06-10 15:45:59,560 INFO E:\New api\newpro\newapp\models.py changed, reloading. 266 
2023-06-10 15:46:01,409 INFO Watching for file changes with StatReloader 668 
2023-06-10 15:48:17,394 INFO Watching for file changes with StatReloader 668 
2023-06-10 15:54:44,499 INFO E:\New api\newpro\newapp\models.py changed, reloading. 266 
2023-06-10 15:54:45,798 INFO Watching for file changes with StatReloader 668 
2023-06-10 15:54:57,624 INFO E:\New api\newpro\newapp\serializers.py changed, reloading. 266 
2023-06-10 15:54:58,906 INFO Watching for file changes with StatReloader 668 
2023-06-10 15:56:33,284 INFO "POST /test HTTP/1.1" 200 46 212 
2023-06-10 15:59:38,814 WARNING Not Found: /test 241 
2023-06-10 15:59:38,814 WARNING "POST /test HTTP/1.1" 404 125 212 
2023-06-10 16:04:19,624 WARNING Not Found: /test 241 
2023-06-10 16:04:19,625 WARNING "POST /test HTTP/1.1" 404 173 212 
2023-06-10 16:04:36,928 INFO "POST /test HTTP/1.1" 200 46 212 
2023-06-10 16:14:35,358 INFO E:\New api\newpro\newapp\views.py changed, reloading. 266 
2023-06-10 16:14:36,652 INFO Watching for file changes with StatReloader 668 
2023-06-10 16:14:48,002 WARNING Bad Request: /test 241 
2023-06-10 16:14:48,003 WARNING "POST /test HTTP/1.1" 400 73 212 
2023-06-10 16:15:04,453 WARNING Bad Request: /test 241 
2023-06-10 16:15:04,453 WARNING "POST /test HTTP/1.1" 400 73 212 
2023-06-10 16:15:14,148 WARNING Not Found: /test 241 
2023-06-10 16:15:14,149 WARNING "POST /test HTTP/1.1" 404 69 212 
2023-06-10 16:15:23,074 WARNING Bad Request: /test 241 
2023-06-10 16:15:23,083 WARNING "POST /test HTTP/1.1" 400 73 212 
2023-06-10 16:15:31,598 WARNING Bad Request: /test 241 
2023-06-10 16:15:31,598 WARNING "POST /test HTTP/1.1" 400 73 212 
2023-06-10 16:15:37,977 WARNING Not Found: /test 241 
2023-06-10 16:15:37,978 WARNING "POST /test HTTP/1.1" 404 69 212 
2023-06-10 16:18:25,705 WARNING Not Found: /test 241 
2023-06-10 16:18:25,705 WARNING "POST /test HTTP/1.1" 404 112 212 
2023-06-10 16:18:45,757 WARNING Not Found: /test 241 
2023-06-10 16:18:45,757 WARNING "POST /test HTTP/1.1" 404 112 212 
2023-06-10 16:19:00,756 INFO E:\New api\newpro\newapp\serializers.py changed, reloading. 266 
2023-06-10 16:19:02,126 INFO Watching for file changes with StatReloader 668 
2023-06-10 16:21:47,867 INFO Watching for file changes with StatReloader 668 
2023-06-10 16:21:55,965 WARNING Not Found: /test 241 
2023-06-10 16:21:55,966 WARNING "POST /test HTTP/1.1" 404 106 212 
2023-06-10 16:39:35,958 INFO E:\New api\newpro\newapp\views.py changed, reloading. 266 
2023-06-10 16:39:37,270 INFO Watching for file changes with StatReloader 668 
2023-06-11 19:51:44,211 INFO Watching for file changes with StatReloader 668 
2023-06-11 19:52:33,742 ERROR Internal Server Error: /test 241 
Traceback (most recent call last):
  File "C:\Python311\Lib\site-packages\django\core\handlers\exception.py", line 55, in inner
    response = get_response(request)
               ^^^^^^^^^^^^^^^^^^^^^
  File "C:\Python311\Lib\site-packages\django\core\handlers\base.py", line 197, in _get_response
    response = wrapped_callback(request, *callback_args, **callback_kwargs)
               ^^^^^^^^^^^^^^^^^^^^^^^^^^^^^^^^^^^^^^^^^^^^^^^^^^^^^^^^^^^^
  File "C:\Python311\Lib\site-packages\django\views\decorators\csrf.py", line 56, in wrapper_view
    return view_func(*args, **kwargs)
           ^^^^^^^^^^^^^^^^^^^^^^^^^^
  File "C:\Python311\Lib\site-packages\django\views\generic\base.py", line 104, in view
    return self.dispatch(request, *args, **kwargs)
           ^^^^^^^^^^^^^^^^^^^^^^^^^^^^^^^^^^^^^^^
  File "C:\Python311\Lib\site-packages\rest_framework\views.py", line 509, in dispatch
    response = self.handle_exception(exc)
               ^^^^^^^^^^^^^^^^^^^^^^^^^^
  File "C:\Python311\Lib\site-packages\rest_framework\views.py", line 469, in handle_exception
    self.raise_uncaught_exception(exc)
  File "C:\Python311\Lib\site-packages\rest_framework\views.py", line 480, in raise_uncaught_exception
    raise exc
  File "C:\Python311\Lib\site-packages\rest_framework\views.py", line 506, in dispatch
    response = handler(request, *args, **kwargs)
               ^^^^^^^^^^^^^^^^^^^^^^^^^^^^^^^^^
  File "E:\New api\newpro\newapp\views.py", line 35, in post
    return JsonResponse({"responseCode":global_msg.UNSUCCESS_RESPONSE_CODE,"response":"Something went Wrong", "error":serializer.errors}, status=status.HTTP_404_NOT_FOUND)
                                       ^^^^^^^^^^^^^^^^^^^^^^^^^^^^^^^^^^
AttributeError: module 'newpro.global_msg' has no attribute 'UNSUCCESS_RESPONSE_CODE'
2023-06-11 19:52:33,746 ERROR "POST /test HTTP/1.1" 500 89782 212 
2023-06-11 19:52:43,258 ERROR Internal Server Error: /test 241 
Traceback (most recent call last):
  File "C:\Python311\Lib\site-packages\django\core\handlers\exception.py", line 55, in inner
    response = get_response(request)
               ^^^^^^^^^^^^^^^^^^^^^
  File "C:\Python311\Lib\site-packages\django\core\handlers\base.py", line 197, in _get_response
    response = wrapped_callback(request, *callback_args, **callback_kwargs)
               ^^^^^^^^^^^^^^^^^^^^^^^^^^^^^^^^^^^^^^^^^^^^^^^^^^^^^^^^^^^^
  File "C:\Python311\Lib\site-packages\django\views\decorators\csrf.py", line 56, in wrapper_view
    return view_func(*args, **kwargs)
           ^^^^^^^^^^^^^^^^^^^^^^^^^^
  File "C:\Python311\Lib\site-packages\django\views\generic\base.py", line 104, in view
    return self.dispatch(request, *args, **kwargs)
           ^^^^^^^^^^^^^^^^^^^^^^^^^^^^^^^^^^^^^^^
  File "C:\Python311\Lib\site-packages\rest_framework\views.py", line 509, in dispatch
    response = self.handle_exception(exc)
               ^^^^^^^^^^^^^^^^^^^^^^^^^^
  File "C:\Python311\Lib\site-packages\rest_framework\views.py", line 469, in handle_exception
    self.raise_uncaught_exception(exc)
  File "C:\Python311\Lib\site-packages\rest_framework\views.py", line 480, in raise_uncaught_exception
    raise exc
  File "C:\Python311\Lib\site-packages\rest_framework\views.py", line 506, in dispatch
    response = handler(request, *args, **kwargs)
               ^^^^^^^^^^^^^^^^^^^^^^^^^^^^^^^^^
  File "E:\New api\newpro\newapp\views.py", line 35, in post
    return JsonResponse({"responseCode":global_msg.UNSUCCESS_RESPONSE_CODE,"response":"Something went Wrong", "error":serializer.errors}, status=status.HTTP_404_NOT_FOUND)
                                       ^^^^^^^^^^^^^^^^^^^^^^^^^^^^^^^^^^
AttributeError: module 'newpro.global_msg' has no attribute 'UNSUCCESS_RESPONSE_CODE'
2023-06-11 19:52:43,260 ERROR "POST /test HTTP/1.1" 500 89782 212 
2023-06-11 19:54:27,610 INFO Watching for file changes with StatReloader 668 
2023-06-11 19:54:55,385 ERROR Internal Server Error: /test 241 
Traceback (most recent call last):
  File "C:\Python311\Lib\site-packages\django\core\handlers\exception.py", line 55, in inner
    response = get_response(request)
               ^^^^^^^^^^^^^^^^^^^^^
  File "C:\Python311\Lib\site-packages\django\core\handlers\base.py", line 197, in _get_response
    response = wrapped_callback(request, *callback_args, **callback_kwargs)
               ^^^^^^^^^^^^^^^^^^^^^^^^^^^^^^^^^^^^^^^^^^^^^^^^^^^^^^^^^^^^
  File "C:\Python311\Lib\site-packages\django\views\decorators\csrf.py", line 56, in wrapper_view
    return view_func(*args, **kwargs)
           ^^^^^^^^^^^^^^^^^^^^^^^^^^
  File "C:\Python311\Lib\site-packages\django\views\generic\base.py", line 104, in view
    return self.dispatch(request, *args, **kwargs)
           ^^^^^^^^^^^^^^^^^^^^^^^^^^^^^^^^^^^^^^^
  File "C:\Python311\Lib\site-packages\rest_framework\views.py", line 509, in dispatch
    response = self.handle_exception(exc)
               ^^^^^^^^^^^^^^^^^^^^^^^^^^
  File "C:\Python311\Lib\site-packages\rest_framework\views.py", line 469, in handle_exception
    self.raise_uncaught_exception(exc)
  File "C:\Python311\Lib\site-packages\rest_framework\views.py", line 480, in raise_uncaught_exception
    raise exc
  File "C:\Python311\Lib\site-packages\rest_framework\views.py", line 506, in dispatch
    response = handler(request, *args, **kwargs)
               ^^^^^^^^^^^^^^^^^^^^^^^^^^^^^^^^^
  File "E:\New api\newpro\newapp\views.py", line 35, in post
    return JsonResponse({"responseCode":global_msg.UNSUCCESS_RESPONSE_CODE,"response":"Something went Wrong", "error":serializer.errors}, status=status.HTTP_404_NOT_FOUND)
                                       ^^^^^^^^^^^^^^^^^^^^^^^^^^^^^^^^^^
AttributeError: module 'newpro.global_msg' has no attribute 'UNSUCCESS_RESPONSE_CODE'
2023-06-11 19:54:55,390 ERROR "POST /test HTTP/1.1" 500 89782 212 
2023-06-11 19:55:12,072 ERROR Internal Server Error: /test 241 
Traceback (most recent call last):
  File "E:\New api\newpro\newapp\views.py", line 24, in get
    return JsonResponse({"responseCode":global_msg.SUCCESS_RESPONSE_CODE, "response":"success", "data": serializer.data},status=status.HTTP_200_OK)
                                       ^^^^^^^^^^^^^^^^^^^^^^^^^^^^^^^^
AttributeError: module 'newpro.global_msg' has no attribute 'SUCCESS_RESPONSE_CODE'

During handling of the above exception, another exception occurred:

Traceback (most recent call last):
  File "C:\Python311\Lib\site-packages\django\core\handlers\exception.py", line 55, in inner
    response = get_response(request)
               ^^^^^^^^^^^^^^^^^^^^^
  File "C:\Python311\Lib\site-packages\django\core\handlers\base.py", line 197, in _get_response
    response = wrapped_callback(request, *callback_args, **callback_kwargs)
               ^^^^^^^^^^^^^^^^^^^^^^^^^^^^^^^^^^^^^^^^^^^^^^^^^^^^^^^^^^^^
  File "C:\Python311\Lib\site-packages\django\views\decorators\csrf.py", line 56, in wrapper_view
    return view_func(*args, **kwargs)
           ^^^^^^^^^^^^^^^^^^^^^^^^^^
  File "C:\Python311\Lib\site-packages\django\views\generic\base.py", line 104, in view
    return self.dispatch(request, *args, **kwargs)
           ^^^^^^^^^^^^^^^^^^^^^^^^^^^^^^^^^^^^^^^
  File "C:\Python311\Lib\site-packages\rest_framework\views.py", line 509, in dispatch
    response = self.handle_exception(exc)
               ^^^^^^^^^^^^^^^^^^^^^^^^^^
  File "C:\Python311\Lib\site-packages\rest_framework\views.py", line 469, in handle_exception
    self.raise_uncaught_exception(exc)
  File "C:\Python311\Lib\site-packages\rest_framework\views.py", line 480, in raise_uncaught_exception
    raise exc
  File "C:\Python311\Lib\site-packages\rest_framework\views.py", line 506, in dispatch
    response = handler(request, *args, **kwargs)
               ^^^^^^^^^^^^^^^^^^^^^^^^^^^^^^^^^
  File "E:\New api\newpro\newapp\views.py", line 26, in get
    logger.info(str(e), exe_info=True)
  File "C:\Python311\Lib\logging\__init__.py", line 1489, in info
    self._log(INFO, msg, args, **kwargs)
TypeError: Logger._log() got an unexpected keyword argument 'exe_info'
2023-06-11 19:55:12,077 ERROR "GET /test HTTP/1.1" 500 100954 212 
2023-06-11 19:56:07,766 ERROR Internal Server Error: /test 241 
Traceback (most recent call last):
  File "E:\New api\newpro\newapp\views.py", line 24, in get
    return JsonResponse({"responseCode":global_msg.SUCCESS_RESPONSE_CODE, "response":"success", "data": serializer.data},status=status.HTTP_200_OK)
                                       ^^^^^^^^^^^^^^^^^^^^^^^^^^^^^^^^
AttributeError: module 'newpro.global_msg' has no attribute 'SUCCESS_RESPONSE_CODE'

During handling of the above exception, another exception occurred:

Traceback (most recent call last):
  File "C:\Python311\Lib\site-packages\django\core\handlers\exception.py", line 55, in inner
    response = get_response(request)
               ^^^^^^^^^^^^^^^^^^^^^
  File "C:\Python311\Lib\site-packages\django\core\handlers\base.py", line 197, in _get_response
    response = wrapped_callback(request, *callback_args, **callback_kwargs)
               ^^^^^^^^^^^^^^^^^^^^^^^^^^^^^^^^^^^^^^^^^^^^^^^^^^^^^^^^^^^^
  File "C:\Python311\Lib\site-packages\django\views\decorators\csrf.py", line 56, in wrapper_view
    return view_func(*args, **kwargs)
           ^^^^^^^^^^^^^^^^^^^^^^^^^^
  File "C:\Python311\Lib\site-packages\django\views\generic\base.py", line 104, in view
    return self.dispatch(request, *args, **kwargs)
           ^^^^^^^^^^^^^^^^^^^^^^^^^^^^^^^^^^^^^^^
  File "C:\Python311\Lib\site-packages\rest_framework\views.py", line 509, in dispatch
    response = self.handle_exception(exc)
               ^^^^^^^^^^^^^^^^^^^^^^^^^^
  File "C:\Python311\Lib\site-packages\rest_framework\views.py", line 469, in handle_exception
    self.raise_uncaught_exception(exc)
  File "C:\Python311\Lib\site-packages\rest_framework\views.py", line 480, in raise_uncaught_exception
    raise exc
  File "C:\Python311\Lib\site-packages\rest_framework\views.py", line 506, in dispatch
    response = handler(request, *args, **kwargs)
               ^^^^^^^^^^^^^^^^^^^^^^^^^^^^^^^^^
  File "E:\New api\newpro\newapp\views.py", line 26, in get
    logger.info(str(e), exe_info=True)
  File "C:\Python311\Lib\logging\__init__.py", line 1489, in info
    self._log(INFO, msg, args, **kwargs)
TypeError: Logger._log() got an unexpected keyword argument 'exe_info'
2023-06-11 19:56:07,769 ERROR "GET /test HTTP/1.1" 500 100954 212 
2023-06-11 19:56:34,379 INFO E:\New api\newpro\newapp\models.py changed, reloading. 266 
2023-06-11 19:56:35,855 INFO Watching for file changes with StatReloader 668 
2023-06-11 20:01:54,813 INFO E:\New api\newpro\newapp\views.py changed, reloading. 266 
2023-06-11 20:01:56,096 INFO Watching for file changes with StatReloader 668 
2023-06-11 20:02:01,921 ERROR Internal Server Error: /test 241 
Traceback (most recent call last):
  File "E:\New api\newpro\newapp\views.py", line 23, in get
    return JsonResponse({"responseCode":global_msg.SUCCESS_RESPONSE_CODE, "response":"success", "data": serializer.data},status=status.HTTP_200_OK)
                                       ^^^^^^^^^^^^^^^^^^^^^^^^^^^^^^^^
AttributeError: module 'newpro.global_msg' has no attribute 'SUCCESS_RESPONSE_CODE'

During handling of the above exception, another exception occurred:

Traceback (most recent call last):
  File "C:\Python311\Lib\site-packages\django\core\handlers\exception.py", line 55, in inner
    response = get_response(request)
               ^^^^^^^^^^^^^^^^^^^^^
  File "C:\Python311\Lib\site-packages\django\core\handlers\base.py", line 197, in _get_response
    response = wrapped_callback(request, *callback_args, **callback_kwargs)
               ^^^^^^^^^^^^^^^^^^^^^^^^^^^^^^^^^^^^^^^^^^^^^^^^^^^^^^^^^^^^
  File "C:\Python311\Lib\site-packages\django\views\decorators\csrf.py", line 56, in wrapper_view
    return view_func(*args, **kwargs)
           ^^^^^^^^^^^^^^^^^^^^^^^^^^
  File "C:\Python311\Lib\site-packages\django\views\generic\base.py", line 104, in view
    return self.dispatch(request, *args, **kwargs)
           ^^^^^^^^^^^^^^^^^^^^^^^^^^^^^^^^^^^^^^^
  File "C:\Python311\Lib\site-packages\rest_framework\views.py", line 509, in dispatch
    response = self.handle_exception(exc)
               ^^^^^^^^^^^^^^^^^^^^^^^^^^
  File "C:\Python311\Lib\site-packages\rest_framework\views.py", line 469, in handle_exception
    self.raise_uncaught_exception(exc)
  File "C:\Python311\Lib\site-packages\rest_framework\views.py", line 480, in raise_uncaught_exception
    raise exc
  File "C:\Python311\Lib\site-packages\rest_framework\views.py", line 506, in dispatch
    response = handler(request, *args, **kwargs)
               ^^^^^^^^^^^^^^^^^^^^^^^^^^^^^^^^^
  File "E:\New api\newpro\newapp\views.py", line 25, in get
    logger.info(str(e), exe_info=True)
  File "C:\Python311\Lib\logging\__init__.py", line 1489, in info
    self._log(INFO, msg, args, **kwargs)
TypeError: Logger._log() got an unexpected keyword argument 'exe_info'
2023-06-11 20:02:01,927 ERROR "GET /test HTTP/1.1" 500 100639 212 
2023-06-11 20:02:36,756 ERROR Internal Server Error: /test 241 
Traceback (most recent call last):
  File "C:\Python311\Lib\site-packages\django\core\handlers\exception.py", line 55, in inner
    response = get_response(request)
               ^^^^^^^^^^^^^^^^^^^^^
  File "C:\Python311\Lib\site-packages\django\core\handlers\base.py", line 197, in _get_response
    response = wrapped_callback(request, *callback_args, **callback_kwargs)
               ^^^^^^^^^^^^^^^^^^^^^^^^^^^^^^^^^^^^^^^^^^^^^^^^^^^^^^^^^^^^
  File "C:\Python311\Lib\site-packages\django\views\decorators\csrf.py", line 56, in wrapper_view
    return view_func(*args, **kwargs)
           ^^^^^^^^^^^^^^^^^^^^^^^^^^
  File "C:\Python311\Lib\site-packages\django\views\generic\base.py", line 104, in view
    return self.dispatch(request, *args, **kwargs)
           ^^^^^^^^^^^^^^^^^^^^^^^^^^^^^^^^^^^^^^^
  File "C:\Python311\Lib\site-packages\rest_framework\views.py", line 509, in dispatch
    response = self.handle_exception(exc)
               ^^^^^^^^^^^^^^^^^^^^^^^^^^
  File "C:\Python311\Lib\site-packages\rest_framework\views.py", line 469, in handle_exception
    self.raise_uncaught_exception(exc)
  File "C:\Python311\Lib\site-packages\rest_framework\views.py", line 480, in raise_uncaught_exception
    raise exc
  File "C:\Python311\Lib\site-packages\rest_framework\views.py", line 506, in dispatch
    response = handler(request, *args, **kwargs)
               ^^^^^^^^^^^^^^^^^^^^^^^^^^^^^^^^^
  File "E:\New api\newpro\newapp\views.py", line 34, in post
    return JsonResponse({"responseCode":global_msg.UNSUCCESS_RESPONSE_CODE,"response":"Something went Wrong", "error":serializer.errors}, status=status.HTTP_404_NOT_FOUND)
                                       ^^^^^^^^^^^^^^^^^^^^^^^^^^^^^^^^^^
AttributeError: module 'newpro.global_msg' has no attribute 'UNSUCCESS_RESPONSE_CODE'
2023-06-11 20:02:36,759 ERROR "POST /test HTTP/1.1" 500 89782 212 
2023-06-11 20:02:56,311 ERROR Internal Server Error: /test 241 
Traceback (most recent call last):
  File "C:\Python311\Lib\site-packages\django\core\handlers\exception.py", line 55, in inner
    response = get_response(request)
               ^^^^^^^^^^^^^^^^^^^^^
  File "C:\Python311\Lib\site-packages\django\core\handlers\base.py", line 197, in _get_response
    response = wrapped_callback(request, *callback_args, **callback_kwargs)
               ^^^^^^^^^^^^^^^^^^^^^^^^^^^^^^^^^^^^^^^^^^^^^^^^^^^^^^^^^^^^
  File "C:\Python311\Lib\site-packages\django\views\decorators\csrf.py", line 56, in wrapper_view
    return view_func(*args, **kwargs)
           ^^^^^^^^^^^^^^^^^^^^^^^^^^
  File "C:\Python311\Lib\site-packages\django\views\generic\base.py", line 104, in view
    return self.dispatch(request, *args, **kwargs)
           ^^^^^^^^^^^^^^^^^^^^^^^^^^^^^^^^^^^^^^^
  File "C:\Python311\Lib\site-packages\rest_framework\views.py", line 509, in dispatch
    response = self.handle_exception(exc)
               ^^^^^^^^^^^^^^^^^^^^^^^^^^
  File "C:\Python311\Lib\site-packages\rest_framework\views.py", line 469, in handle_exception
    self.raise_uncaught_exception(exc)
  File "C:\Python311\Lib\site-packages\rest_framework\views.py", line 480, in raise_uncaught_exception
    raise exc
  File "C:\Python311\Lib\site-packages\rest_framework\views.py", line 506, in dispatch
    response = handler(request, *args, **kwargs)
               ^^^^^^^^^^^^^^^^^^^^^^^^^^^^^^^^^
  File "E:\New api\newpro\newapp\views.py", line 34, in post
    return JsonResponse({"responseCode":global_msg.UNSUCCESS_RESPONSE_CODE,"response":"Something went Wrong", "error":serializer.errors}, status=status.HTTP_404_NOT_FOUND)
                                       ^^^^^^^^^^^^^^^^^^^^^^^^^^^^^^^^^^
AttributeError: module 'newpro.global_msg' has no attribute 'UNSUCCESS_RESPONSE_CODE'
2023-06-11 20:02:56,314 ERROR "POST /test HTTP/1.1" 500 89782 212 
2023-06-11 20:14:21,231 ERROR Internal Server Error: /test 241 
Traceback (most recent call last):
  File "C:\Python311\Lib\site-packages\django\core\handlers\exception.py", line 55, in inner
    response = get_response(request)
               ^^^^^^^^^^^^^^^^^^^^^
  File "C:\Python311\Lib\site-packages\django\core\handlers\base.py", line 197, in _get_response
    response = wrapped_callback(request, *callback_args, **callback_kwargs)
               ^^^^^^^^^^^^^^^^^^^^^^^^^^^^^^^^^^^^^^^^^^^^^^^^^^^^^^^^^^^^
  File "C:\Python311\Lib\site-packages\django\views\decorators\csrf.py", line 56, in wrapper_view
    return view_func(*args, **kwargs)
           ^^^^^^^^^^^^^^^^^^^^^^^^^^
  File "C:\Python311\Lib\site-packages\django\views\generic\base.py", line 104, in view
    return self.dispatch(request, *args, **kwargs)
           ^^^^^^^^^^^^^^^^^^^^^^^^^^^^^^^^^^^^^^^
  File "C:\Python311\Lib\site-packages\rest_framework\views.py", line 509, in dispatch
    response = self.handle_exception(exc)
               ^^^^^^^^^^^^^^^^^^^^^^^^^^
  File "C:\Python311\Lib\site-packages\rest_framework\views.py", line 469, in handle_exception
    self.raise_uncaught_exception(exc)
  File "C:\Python311\Lib\site-packages\rest_framework\views.py", line 480, in raise_uncaught_exception
    raise exc
  File "C:\Python311\Lib\site-packages\rest_framework\views.py", line 506, in dispatch
    response = handler(request, *args, **kwargs)
               ^^^^^^^^^^^^^^^^^^^^^^^^^^^^^^^^^
  File "E:\New api\newpro\newapp\views.py", line 33, in post
    return JsonResponse({"responseCode":global_msg.SUCCESS_RESPONSE_CODE, "response":"success"},status=status.HTTP_200_OK)
                                       ^^^^^^^^^^^^^^^^^^^^^^^^^^^^^^^^
AttributeError: module 'newpro.global_msg' has no attribute 'SUCCESS_RESPONSE_CODE'
2023-06-11 20:14:21,234 ERROR "POST /test HTTP/1.1" 500 90140 212 
2023-06-11 20:15:42,915 WARNING Not Found: / 241 
2023-06-11 20:15:42,916 WARNING "POST / HTTP/1.1" 404 2224 212 
2023-06-11 20:15:56,340 ERROR Internal Server Error: /test 241 
Traceback (most recent call last):
  File "C:\Python311\Lib\site-packages\django\core\handlers\exception.py", line 55, in inner
    response = get_response(request)
               ^^^^^^^^^^^^^^^^^^^^^
  File "C:\Python311\Lib\site-packages\django\core\handlers\base.py", line 197, in _get_response
    response = wrapped_callback(request, *callback_args, **callback_kwargs)
               ^^^^^^^^^^^^^^^^^^^^^^^^^^^^^^^^^^^^^^^^^^^^^^^^^^^^^^^^^^^^
  File "C:\Python311\Lib\site-packages\django\views\decorators\csrf.py", line 56, in wrapper_view
    return view_func(*args, **kwargs)
           ^^^^^^^^^^^^^^^^^^^^^^^^^^
  File "C:\Python311\Lib\site-packages\django\views\generic\base.py", line 104, in view
    return self.dispatch(request, *args, **kwargs)
           ^^^^^^^^^^^^^^^^^^^^^^^^^^^^^^^^^^^^^^^
  File "C:\Python311\Lib\site-packages\rest_framework\views.py", line 509, in dispatch
    response = self.handle_exception(exc)
               ^^^^^^^^^^^^^^^^^^^^^^^^^^
  File "C:\Python311\Lib\site-packages\rest_framework\views.py", line 469, in handle_exception
    self.raise_uncaught_exception(exc)
  File "C:\Python311\Lib\site-packages\rest_framework\views.py", line 480, in raise_uncaught_exception
    raise exc
  File "C:\Python311\Lib\site-packages\rest_framework\views.py", line 506, in dispatch
    response = handler(request, *args, **kwargs)
               ^^^^^^^^^^^^^^^^^^^^^^^^^^^^^^^^^
  File "E:\New api\newpro\newapp\views.py", line 34, in post
    return JsonResponse({"responseCode":global_msg.UNSUCCESS_RESPONSE_CODE,"response":"Something went Wrong", "error":serializer.errors}, status=status.HTTP_404_NOT_FOUND)
                                       ^^^^^^^^^^^^^^^^^^^^^^^^^^^^^^^^^^
AttributeError: module 'newpro.global_msg' has no attribute 'UNSUCCESS_RESPONSE_CODE'
2023-06-11 20:15:56,343 ERROR "POST /test HTTP/1.1" 500 89788 212 
2023-06-11 20:18:46,957 INFO E:\New api\newpro\newapp\serializers.py changed, reloading. 266 
2023-06-11 20:18:48,650 INFO Watching for file changes with StatReloader 668 
2023-06-11 20:20:27,516 ERROR Internal Server Error: /test 241 
Traceback (most recent call last):
  File "C:\Python311\Lib\site-packages\django\core\handlers\exception.py", line 55, in inner
    response = get_response(request)
               ^^^^^^^^^^^^^^^^^^^^^
  File "C:\Python311\Lib\site-packages\django\core\handlers\base.py", line 197, in _get_response
    response = wrapped_callback(request, *callback_args, **callback_kwargs)
               ^^^^^^^^^^^^^^^^^^^^^^^^^^^^^^^^^^^^^^^^^^^^^^^^^^^^^^^^^^^^
  File "C:\Python311\Lib\site-packages\django\views\decorators\csrf.py", line 56, in wrapper_view
    return view_func(*args, **kwargs)
           ^^^^^^^^^^^^^^^^^^^^^^^^^^
  File "C:\Python311\Lib\site-packages\django\views\generic\base.py", line 104, in view
    return self.dispatch(request, *args, **kwargs)
           ^^^^^^^^^^^^^^^^^^^^^^^^^^^^^^^^^^^^^^^
  File "C:\Python311\Lib\site-packages\rest_framework\views.py", line 509, in dispatch
    response = self.handle_exception(exc)
               ^^^^^^^^^^^^^^^^^^^^^^^^^^
  File "C:\Python311\Lib\site-packages\rest_framework\views.py", line 469, in handle_exception
    self.raise_uncaught_exception(exc)
  File "C:\Python311\Lib\site-packages\rest_framework\views.py", line 480, in raise_uncaught_exception
    raise exc
  File "C:\Python311\Lib\site-packages\rest_framework\views.py", line 506, in dispatch
    response = handler(request, *args, **kwargs)
               ^^^^^^^^^^^^^^^^^^^^^^^^^^^^^^^^^
  File "E:\New api\newpro\newapp\views.py", line 34, in post
    return JsonResponse({"responseCode":global_msg.UNSUCCESS_RESPONSE_CODE,"response":"Something went Wrong", "error":serializer.errors}, status=status.HTTP_404_NOT_FOUND)
                                       ^^^^^^^^^^^^^^^^^^^^^^^^^^^^^^^^^^
AttributeError: module 'newpro.global_msg' has no attribute 'UNSUCCESS_RESPONSE_CODE'
2023-06-11 20:20:27,520 ERROR "POST /test HTTP/1.1" 500 89788 212 
2023-06-11 20:21:41,161 ERROR Internal Server Error: /test 241 
Traceback (most recent call last):
  File "E:\New api\newpro\newapp\views.py", line 23, in get
    return JsonResponse({"responseCode":global_msg.SUCCESS_RESPONSE_CODE, "response":"success", "data": serializer.data},status=status.HTTP_200_OK)
                                       ^^^^^^^^^^^^^^^^^^^^^^^^^^^^^^^^
AttributeError: module 'newpro.global_msg' has no attribute 'SUCCESS_RESPONSE_CODE'

During handling of the above exception, another exception occurred:

Traceback (most recent call last):
  File "C:\Python311\Lib\site-packages\django\core\handlers\exception.py", line 55, in inner
    response = get_response(request)
               ^^^^^^^^^^^^^^^^^^^^^
  File "C:\Python311\Lib\site-packages\django\core\handlers\base.py", line 197, in _get_response
    response = wrapped_callback(request, *callback_args, **callback_kwargs)
               ^^^^^^^^^^^^^^^^^^^^^^^^^^^^^^^^^^^^^^^^^^^^^^^^^^^^^^^^^^^^
  File "C:\Python311\Lib\site-packages\django\views\decorators\csrf.py", line 56, in wrapper_view
    return view_func(*args, **kwargs)
           ^^^^^^^^^^^^^^^^^^^^^^^^^^
  File "C:\Python311\Lib\site-packages\django\views\generic\base.py", line 104, in view
    return self.dispatch(request, *args, **kwargs)
           ^^^^^^^^^^^^^^^^^^^^^^^^^^^^^^^^^^^^^^^
  File "C:\Python311\Lib\site-packages\rest_framework\views.py", line 509, in dispatch
    response = self.handle_exception(exc)
               ^^^^^^^^^^^^^^^^^^^^^^^^^^
  File "C:\Python311\Lib\site-packages\rest_framework\views.py", line 469, in handle_exception
    self.raise_uncaught_exception(exc)
  File "C:\Python311\Lib\site-packages\rest_framework\views.py", line 480, in raise_uncaught_exception
    raise exc
  File "C:\Python311\Lib\site-packages\rest_framework\views.py", line 506, in dispatch
    response = handler(request, *args, **kwargs)
               ^^^^^^^^^^^^^^^^^^^^^^^^^^^^^^^^^
  File "E:\New api\newpro\newapp\views.py", line 25, in get
    logger.info(str(e), exe_info=True)
  File "C:\Python311\Lib\logging\__init__.py", line 1489, in info
    self._log(INFO, msg, args, **kwargs)
TypeError: Logger._log() got an unexpected keyword argument 'exe_info'
2023-06-11 20:21:41,166 ERROR "GET /test HTTP/1.1" 500 100791 212 
2023-06-11 20:24:13,654 INFO E:\New api\newpro\newapp\views.py changed, reloading. 266 
2023-06-11 20:24:14,965 INFO Watching for file changes with StatReloader 668 
2023-06-11 20:24:22,084 INFO module 'newpro.global_msg' has no attribute 'SUCCESS_RESPONSE_CODE' 25 
Traceback (most recent call last):
  File "E:\New api\newpro\newapp\views.py", line 23, in get
    return JsonResponse({"responseCode":global_msg.SUCCESS_RESPONSE_CODE, "response":"success", "data": serializer.data},status=status.HTTP_200_OK)
                                       ^^^^^^^^^^^^^^^^^^^^^^^^^^^^^^^^
AttributeError: module 'newpro.global_msg' has no attribute 'SUCCESS_RESPONSE_CODE'
2023-06-11 20:24:22,298 ERROR Internal Server Error: /test 241 
Traceback (most recent call last):
  File "E:\New api\newpro\newapp\views.py", line 23, in get
    return JsonResponse({"responseCode":global_msg.SUCCESS_RESPONSE_CODE, "response":"success", "data": serializer.data},status=status.HTTP_200_OK)
                                       ^^^^^^^^^^^^^^^^^^^^^^^^^^^^^^^^
AttributeError: module 'newpro.global_msg' has no attribute 'SUCCESS_RESPONSE_CODE'

During handling of the above exception, another exception occurred:

Traceback (most recent call last):
  File "C:\Python311\Lib\site-packages\django\core\handlers\exception.py", line 55, in inner
    response = get_response(request)
               ^^^^^^^^^^^^^^^^^^^^^
  File "C:\Python311\Lib\site-packages\django\core\handlers\base.py", line 197, in _get_response
    response = wrapped_callback(request, *callback_args, **callback_kwargs)
               ^^^^^^^^^^^^^^^^^^^^^^^^^^^^^^^^^^^^^^^^^^^^^^^^^^^^^^^^^^^^
  File "C:\Python311\Lib\site-packages\django\views\decorators\csrf.py", line 56, in wrapper_view
    return view_func(*args, **kwargs)
           ^^^^^^^^^^^^^^^^^^^^^^^^^^
  File "C:\Python311\Lib\site-packages\django\views\generic\base.py", line 104, in view
    return self.dispatch(request, *args, **kwargs)
           ^^^^^^^^^^^^^^^^^^^^^^^^^^^^^^^^^^^^^^^
  File "C:\Python311\Lib\site-packages\rest_framework\views.py", line 509, in dispatch
    response = self.handle_exception(exc)
               ^^^^^^^^^^^^^^^^^^^^^^^^^^
  File "C:\Python311\Lib\site-packages\rest_framework\views.py", line 469, in handle_exception
    self.raise_uncaught_exception(exc)
  File "C:\Python311\Lib\site-packages\rest_framework\views.py", line 480, in raise_uncaught_exception
    raise exc
  File "C:\Python311\Lib\site-packages\rest_framework\views.py", line 506, in dispatch
    response = handler(request, *args, **kwargs)
               ^^^^^^^^^^^^^^^^^^^^^^^^^^^^^^^^^
  File "E:\New api\newpro\newapp\views.py", line 26, in get
    return JsonResponse({"responseCode":global_msg.UNSUCCESS_RESPONSE_CODE,"response":"Data not Found"}, status=status.HTTP_404_NOT_FOUND)
                                       ^^^^^^^^^^^^^^^^^^^^^^^^^^^^^^^^^^
AttributeError: module 'newpro.global_msg' has no attribute 'UNSUCCESS_RESPONSE_CODE'
2023-06-11 20:24:22,304 ERROR "GET /test HTTP/1.1" 500 96978 212 
2023-06-11 20:24:25,648 INFO module 'newpro.global_msg' has no attribute 'SUCCESS_RESPONSE_CODE' 25 
Traceback (most recent call last):
  File "E:\New api\newpro\newapp\views.py", line 23, in get
    return JsonResponse({"responseCode":global_msg.SUCCESS_RESPONSE_CODE, "response":"success", "data": serializer.data},status=status.HTTP_200_OK)
                                       ^^^^^^^^^^^^^^^^^^^^^^^^^^^^^^^^
AttributeError: module 'newpro.global_msg' has no attribute 'SUCCESS_RESPONSE_CODE'
2023-06-11 20:24:25,830 ERROR Internal Server Error: /test 241 
Traceback (most recent call last):
  File "E:\New api\newpro\newapp\views.py", line 23, in get
    return JsonResponse({"responseCode":global_msg.SUCCESS_RESPONSE_CODE, "response":"success", "data": serializer.data},status=status.HTTP_200_OK)
                                       ^^^^^^^^^^^^^^^^^^^^^^^^^^^^^^^^
AttributeError: module 'newpro.global_msg' has no attribute 'SUCCESS_RESPONSE_CODE'

During handling of the above exception, another exception occurred:

Traceback (most recent call last):
  File "C:\Python311\Lib\site-packages\django\core\handlers\exception.py", line 55, in inner
    response = get_response(request)
               ^^^^^^^^^^^^^^^^^^^^^
  File "C:\Python311\Lib\site-packages\django\core\handlers\base.py", line 197, in _get_response
    response = wrapped_callback(request, *callback_args, **callback_kwargs)
               ^^^^^^^^^^^^^^^^^^^^^^^^^^^^^^^^^^^^^^^^^^^^^^^^^^^^^^^^^^^^
  File "C:\Python311\Lib\site-packages\django\views\decorators\csrf.py", line 56, in wrapper_view
    return view_func(*args, **kwargs)
           ^^^^^^^^^^^^^^^^^^^^^^^^^^
  File "C:\Python311\Lib\site-packages\django\views\generic\base.py", line 104, in view
    return self.dispatch(request, *args, **kwargs)
           ^^^^^^^^^^^^^^^^^^^^^^^^^^^^^^^^^^^^^^^
  File "C:\Python311\Lib\site-packages\rest_framework\views.py", line 509, in dispatch
    response = self.handle_exception(exc)
               ^^^^^^^^^^^^^^^^^^^^^^^^^^
  File "C:\Python311\Lib\site-packages\rest_framework\views.py", line 469, in handle_exception
    self.raise_uncaught_exception(exc)
  File "C:\Python311\Lib\site-packages\rest_framework\views.py", line 480, in raise_uncaught_exception
    raise exc
  File "C:\Python311\Lib\site-packages\rest_framework\views.py", line 506, in dispatch
    response = handler(request, *args, **kwargs)
               ^^^^^^^^^^^^^^^^^^^^^^^^^^^^^^^^^
  File "E:\New api\newpro\newapp\views.py", line 26, in get
    return JsonResponse({"responseCode":global_msg.UNSUCCESS_RESPONSE_CODE,"response":"Data not Found"}, status=status.HTTP_404_NOT_FOUND)
                                       ^^^^^^^^^^^^^^^^^^^^^^^^^^^^^^^^^^
AttributeError: module 'newpro.global_msg' has no attribute 'UNSUCCESS_RESPONSE_CODE'
2023-06-11 20:24:25,833 ERROR "GET /test HTTP/1.1" 500 96978 212 
2023-06-11 20:30:22,156 INFO module 'newpro.global_msg' has no attribute 'SUCCESS_RESPONSE_CODE' 25 
Traceback (most recent call last):
  File "E:\New api\newpro\newapp\views.py", line 23, in get
    return JsonResponse({"responseCode":global_msg.SUCCESS_RESPONSE_CODE, "response":"success", "data": serializer.data},status=status.HTTP_200_OK)
                                       ^^^^^^^^^^^^^^^^^^^^^^^^^^^^^^^^
AttributeError: module 'newpro.global_msg' has no attribute 'SUCCESS_RESPONSE_CODE'
2023-06-11 20:30:22,304 ERROR Internal Server Error: /test 241 
Traceback (most recent call last):
  File "E:\New api\newpro\newapp\views.py", line 23, in get
    return JsonResponse({"responseCode":global_msg.SUCCESS_RESPONSE_CODE, "response":"success", "data": serializer.data},status=status.HTTP_200_OK)
                                       ^^^^^^^^^^^^^^^^^^^^^^^^^^^^^^^^
AttributeError: module 'newpro.global_msg' has no attribute 'SUCCESS_RESPONSE_CODE'

During handling of the above exception, another exception occurred:

Traceback (most recent call last):
  File "C:\Python311\Lib\site-packages\django\core\handlers\exception.py", line 55, in inner
    response = get_response(request)
               ^^^^^^^^^^^^^^^^^^^^^
  File "C:\Python311\Lib\site-packages\django\core\handlers\base.py", line 197, in _get_response
    response = wrapped_callback(request, *callback_args, **callback_kwargs)
               ^^^^^^^^^^^^^^^^^^^^^^^^^^^^^^^^^^^^^^^^^^^^^^^^^^^^^^^^^^^^
  File "C:\Python311\Lib\site-packages\django\views\decorators\csrf.py", line 56, in wrapper_view
    return view_func(*args, **kwargs)
           ^^^^^^^^^^^^^^^^^^^^^^^^^^
  File "C:\Python311\Lib\site-packages\django\views\generic\base.py", line 104, in view
    return self.dispatch(request, *args, **kwargs)
           ^^^^^^^^^^^^^^^^^^^^^^^^^^^^^^^^^^^^^^^
  File "C:\Python311\Lib\site-packages\rest_framework\views.py", line 509, in dispatch
    response = self.handle_exception(exc)
               ^^^^^^^^^^^^^^^^^^^^^^^^^^
  File "C:\Python311\Lib\site-packages\rest_framework\views.py", line 469, in handle_exception
    self.raise_uncaught_exception(exc)
  File "C:\Python311\Lib\site-packages\rest_framework\views.py", line 480, in raise_uncaught_exception
    raise exc
  File "C:\Python311\Lib\site-packages\rest_framework\views.py", line 506, in dispatch
    response = handler(request, *args, **kwargs)
               ^^^^^^^^^^^^^^^^^^^^^^^^^^^^^^^^^
  File "E:\New api\newpro\newapp\views.py", line 26, in get
    return JsonResponse({"responseCode":global_msg.UNSUCCESS_RESPONSE_CODE,"response":"Data not Found"}, status=status.HTTP_404_NOT_FOUND)
                                       ^^^^^^^^^^^^^^^^^^^^^^^^^^^^^^^^^^
AttributeError: module 'newpro.global_msg' has no attribute 'UNSUCCESS_RESPONSE_CODE'
2023-06-11 20:30:22,306 ERROR "GET /test HTTP/1.1" 500 96978 212 
2023-06-11 20:30:25,120 INFO module 'newpro.global_msg' has no attribute 'SUCCESS_RESPONSE_CODE' 25 
Traceback (most recent call last):
  File "E:\New api\newpro\newapp\views.py", line 23, in get
    return JsonResponse({"responseCode":global_msg.SUCCESS_RESPONSE_CODE, "response":"success", "data": serializer.data},status=status.HTTP_200_OK)
                                       ^^^^^^^^^^^^^^^^^^^^^^^^^^^^^^^^
AttributeError: module 'newpro.global_msg' has no attribute 'SUCCESS_RESPONSE_CODE'
2023-06-11 20:30:25,325 ERROR Internal Server Error: /test 241 
Traceback (most recent call last):
  File "E:\New api\newpro\newapp\views.py", line 23, in get
    return JsonResponse({"responseCode":global_msg.SUCCESS_RESPONSE_CODE, "response":"success", "data": serializer.data},status=status.HTTP_200_OK)
                                       ^^^^^^^^^^^^^^^^^^^^^^^^^^^^^^^^
AttributeError: module 'newpro.global_msg' has no attribute 'SUCCESS_RESPONSE_CODE'

During handling of the above exception, another exception occurred:

Traceback (most recent call last):
  File "C:\Python311\Lib\site-packages\django\core\handlers\exception.py", line 55, in inner
    response = get_response(request)
               ^^^^^^^^^^^^^^^^^^^^^
  File "C:\Python311\Lib\site-packages\django\core\handlers\base.py", line 197, in _get_response
    response = wrapped_callback(request, *callback_args, **callback_kwargs)
               ^^^^^^^^^^^^^^^^^^^^^^^^^^^^^^^^^^^^^^^^^^^^^^^^^^^^^^^^^^^^
  File "C:\Python311\Lib\site-packages\django\views\decorators\csrf.py", line 56, in wrapper_view
    return view_func(*args, **kwargs)
           ^^^^^^^^^^^^^^^^^^^^^^^^^^
  File "C:\Python311\Lib\site-packages\django\views\generic\base.py", line 104, in view
    return self.dispatch(request, *args, **kwargs)
           ^^^^^^^^^^^^^^^^^^^^^^^^^^^^^^^^^^^^^^^
  File "C:\Python311\Lib\site-packages\rest_framework\views.py", line 509, in dispatch
    response = self.handle_exception(exc)
               ^^^^^^^^^^^^^^^^^^^^^^^^^^
  File "C:\Python311\Lib\site-packages\rest_framework\views.py", line 469, in handle_exception
    self.raise_uncaught_exception(exc)
  File "C:\Python311\Lib\site-packages\rest_framework\views.py", line 480, in raise_uncaught_exception
    raise exc
  File "C:\Python311\Lib\site-packages\rest_framework\views.py", line 506, in dispatch
    response = handler(request, *args, **kwargs)
               ^^^^^^^^^^^^^^^^^^^^^^^^^^^^^^^^^
  File "E:\New api\newpro\newapp\views.py", line 26, in get
    return JsonResponse({"responseCode":global_msg.UNSUCCESS_RESPONSE_CODE,"response":"Data not Found"}, status=status.HTTP_404_NOT_FOUND)
                                       ^^^^^^^^^^^^^^^^^^^^^^^^^^^^^^^^^^
AttributeError: module 'newpro.global_msg' has no attribute 'UNSUCCESS_RESPONSE_CODE'
2023-06-11 20:30:25,332 ERROR "GET /test HTTP/1.1" 500 96978 212 
2023-06-11 20:43:37,406 INFO E:\New api\newpro\newapp\views.py changed, reloading. 266 
2023-06-11 20:43:38,779 INFO Watching for file changes with StatReloader 668 
2023-06-11 20:43:50,263 INFO module 'newpro.global_msg' has no attribute 'SUCCESS_RESPONSE_CODE' 25 
Traceback (most recent call last):
  File "E:\New api\newpro\newapp\views.py", line 23, in get
    return JsonResponse({"responseCode":global_msg.SUCCESS_RESPONSE_CODE, "response":"success", "data": serializer.data},status=status.HTTP_200_OK)
                                       ^^^^^^^^^^^^^^^^^^^^^^^^^^^^^^^^
AttributeError: module 'newpro.global_msg' has no attribute 'SUCCESS_RESPONSE_CODE'
2023-06-11 20:43:50,442 ERROR Internal Server Error: /test 241 
Traceback (most recent call last):
  File "E:\New api\newpro\newapp\views.py", line 23, in get
    return JsonResponse({"responseCode":global_msg.SUCCESS_RESPONSE_CODE, "response":"success", "data": serializer.data},status=status.HTTP_200_OK)
                                       ^^^^^^^^^^^^^^^^^^^^^^^^^^^^^^^^
AttributeError: module 'newpro.global_msg' has no attribute 'SUCCESS_RESPONSE_CODE'

During handling of the above exception, another exception occurred:

Traceback (most recent call last):
  File "C:\Python311\Lib\site-packages\django\core\handlers\exception.py", line 55, in inner
    response = get_response(request)
               ^^^^^^^^^^^^^^^^^^^^^
  File "C:\Python311\Lib\site-packages\django\core\handlers\base.py", line 197, in _get_response
    response = wrapped_callback(request, *callback_args, **callback_kwargs)
               ^^^^^^^^^^^^^^^^^^^^^^^^^^^^^^^^^^^^^^^^^^^^^^^^^^^^^^^^^^^^
  File "C:\Python311\Lib\site-packages\django\views\decorators\csrf.py", line 56, in wrapper_view
    return view_func(*args, **kwargs)
           ^^^^^^^^^^^^^^^^^^^^^^^^^^
  File "C:\Python311\Lib\site-packages\django\views\generic\base.py", line 104, in view
    return self.dispatch(request, *args, **kwargs)
           ^^^^^^^^^^^^^^^^^^^^^^^^^^^^^^^^^^^^^^^
  File "C:\Python311\Lib\site-packages\rest_framework\views.py", line 509, in dispatch
    response = self.handle_exception(exc)
               ^^^^^^^^^^^^^^^^^^^^^^^^^^
  File "C:\Python311\Lib\site-packages\rest_framework\views.py", line 469, in handle_exception
    self.raise_uncaught_exception(exc)
  File "C:\Python311\Lib\site-packages\rest_framework\views.py", line 480, in raise_uncaught_exception
    raise exc
  File "C:\Python311\Lib\site-packages\rest_framework\views.py", line 506, in dispatch
    response = handler(request, *args, **kwargs)
               ^^^^^^^^^^^^^^^^^^^^^^^^^^^^^^^^^
  File "E:\New api\newpro\newapp\views.py", line 26, in get
    return JsonResponse({"responseCode":global_msg.UNSUCCESS_RESPONSE_CODE,"response":"Data not Found"}, status=status.HTTP_404_NOT_FOUND)
                                       ^^^^^^^^^^^^^^^^^^^^^^^^^^^^^^^^^^
AttributeError: module 'newpro.global_msg' has no attribute 'UNSUCCESS_RESPONSE_CODE'
2023-06-11 20:43:50,446 ERROR "GET /test HTTP/1.1" 500 96984 212 
2023-06-11 20:46:41,771 INFO module 'newpro.global_msg' has no attribute 'SUCCESS_RESPONSE_CODE' 25 
Traceback (most recent call last):
  File "E:\New api\newpro\newapp\views.py", line 23, in get
    return JsonResponse({"responseCode":global_msg.SUCCESS_RESPONSE_CODE, "response":"success", "data": serializer.data},status=status.HTTP_200_OK)
                                       ^^^^^^^^^^^^^^^^^^^^^^^^^^^^^^^^
AttributeError: module 'newpro.global_msg' has no attribute 'SUCCESS_RESPONSE_CODE'
2023-06-11 20:46:41,912 ERROR Internal Server Error: /test 241 
Traceback (most recent call last):
  File "E:\New api\newpro\newapp\views.py", line 23, in get
    return JsonResponse({"responseCode":global_msg.SUCCESS_RESPONSE_CODE, "response":"success", "data": serializer.data},status=status.HTTP_200_OK)
                                       ^^^^^^^^^^^^^^^^^^^^^^^^^^^^^^^^
AttributeError: module 'newpro.global_msg' has no attribute 'SUCCESS_RESPONSE_CODE'

During handling of the above exception, another exception occurred:

Traceback (most recent call last):
  File "C:\Python311\Lib\site-packages\django\core\handlers\exception.py", line 55, in inner
    response = get_response(request)
               ^^^^^^^^^^^^^^^^^^^^^
  File "C:\Python311\Lib\site-packages\django\core\handlers\base.py", line 197, in _get_response
    response = wrapped_callback(request, *callback_args, **callback_kwargs)
               ^^^^^^^^^^^^^^^^^^^^^^^^^^^^^^^^^^^^^^^^^^^^^^^^^^^^^^^^^^^^
  File "C:\Python311\Lib\site-packages\django\views\decorators\csrf.py", line 56, in wrapper_view
    return view_func(*args, **kwargs)
           ^^^^^^^^^^^^^^^^^^^^^^^^^^
  File "C:\Python311\Lib\site-packages\django\views\generic\base.py", line 104, in view
    return self.dispatch(request, *args, **kwargs)
           ^^^^^^^^^^^^^^^^^^^^^^^^^^^^^^^^^^^^^^^
  File "C:\Python311\Lib\site-packages\rest_framework\views.py", line 509, in dispatch
    response = self.handle_exception(exc)
               ^^^^^^^^^^^^^^^^^^^^^^^^^^
  File "C:\Python311\Lib\site-packages\rest_framework\views.py", line 469, in handle_exception
    self.raise_uncaught_exception(exc)
  File "C:\Python311\Lib\site-packages\rest_framework\views.py", line 480, in raise_uncaught_exception
    raise exc
  File "C:\Python311\Lib\site-packages\rest_framework\views.py", line 506, in dispatch
    response = handler(request, *args, **kwargs)
               ^^^^^^^^^^^^^^^^^^^^^^^^^^^^^^^^^
  File "E:\New api\newpro\newapp\views.py", line 26, in get
    return JsonResponse({"responseCode":global_msg.UNSUCCESS_RESPONSE_CODE,"response":"Data not Found"}, status=status.HTTP_404_NOT_FOUND)
                                       ^^^^^^^^^^^^^^^^^^^^^^^^^^^^^^^^^^
AttributeError: module 'newpro.global_msg' has no attribute 'UNSUCCESS_RESPONSE_CODE'
2023-06-11 20:46:41,915 ERROR "GET /test HTTP/1.1" 500 96984 212 
2023-06-11 20:46:49,624 ERROR Internal Server Error: /test 241 
Traceback (most recent call last):
  File "C:\Python311\Lib\site-packages\django\core\handlers\exception.py", line 55, in inner
    response = get_response(request)
               ^^^^^^^^^^^^^^^^^^^^^
  File "C:\Python311\Lib\site-packages\django\core\handlers\base.py", line 197, in _get_response
    response = wrapped_callback(request, *callback_args, **callback_kwargs)
               ^^^^^^^^^^^^^^^^^^^^^^^^^^^^^^^^^^^^^^^^^^^^^^^^^^^^^^^^^^^^
  File "C:\Python311\Lib\site-packages\django\views\decorators\csrf.py", line 56, in wrapper_view
    return view_func(*args, **kwargs)
           ^^^^^^^^^^^^^^^^^^^^^^^^^^
  File "C:\Python311\Lib\site-packages\django\views\generic\base.py", line 104, in view
    return self.dispatch(request, *args, **kwargs)
           ^^^^^^^^^^^^^^^^^^^^^^^^^^^^^^^^^^^^^^^
  File "C:\Python311\Lib\site-packages\rest_framework\views.py", line 509, in dispatch
    response = self.handle_exception(exc)
               ^^^^^^^^^^^^^^^^^^^^^^^^^^
  File "C:\Python311\Lib\site-packages\rest_framework\views.py", line 469, in handle_exception
    self.raise_uncaught_exception(exc)
  File "C:\Python311\Lib\site-packages\rest_framework\views.py", line 480, in raise_uncaught_exception
    raise exc
  File "C:\Python311\Lib\site-packages\rest_framework\views.py", line 506, in dispatch
    response = handler(request, *args, **kwargs)
               ^^^^^^^^^^^^^^^^^^^^^^^^^^^^^^^^^
  File "E:\New api\newpro\newapp\views.py", line 33, in post
    return JsonResponse({"responseCode":global_msg.SUCCESS_RESPONSE_CODE, "response":"success"},status=status.HTTP_200_OK)
                                       ^^^^^^^^^^^^^^^^^^^^^^^^^^^^^^^^
AttributeError: module 'newpro.global_msg' has no attribute 'SUCCESS_RESPONSE_CODE'
2023-06-11 20:46:49,627 ERROR "POST /test HTTP/1.1" 500 90142 212 
2023-06-11 20:57:27,222 INFO E:\New api\newpro\newapp\views.py changed, reloading. 266 
2023-06-11 20:57:28,651 INFO Watching for file changes with StatReloader 668 
2023-06-11 20:57:56,803 ERROR Internal Server Error: /test 241 
Traceback (most recent call last):
  File "C:\Python311\Lib\site-packages\django\core\handlers\exception.py", line 55, in inner
    response = get_response(request)
               ^^^^^^^^^^^^^^^^^^^^^
  File "C:\Python311\Lib\site-packages\django\core\handlers\base.py", line 197, in _get_response
    response = wrapped_callback(request, *callback_args, **callback_kwargs)
               ^^^^^^^^^^^^^^^^^^^^^^^^^^^^^^^^^^^^^^^^^^^^^^^^^^^^^^^^^^^^
  File "C:\Python311\Lib\site-packages\django\views\decorators\csrf.py", line 56, in wrapper_view
    return view_func(*args, **kwargs)
           ^^^^^^^^^^^^^^^^^^^^^^^^^^
  File "C:\Python311\Lib\site-packages\django\views\generic\base.py", line 104, in view
    return self.dispatch(request, *args, **kwargs)
           ^^^^^^^^^^^^^^^^^^^^^^^^^^^^^^^^^^^^^^^
  File "C:\Python311\Lib\site-packages\rest_framework\views.py", line 509, in dispatch
    response = self.handle_exception(exc)
               ^^^^^^^^^^^^^^^^^^^^^^^^^^
  File "C:\Python311\Lib\site-packages\rest_framework\views.py", line 469, in handle_exception
    self.raise_uncaught_exception(exc)
  File "C:\Python311\Lib\site-packages\rest_framework\views.py", line 480, in raise_uncaught_exception
    raise exc
  File "C:\Python311\Lib\site-packages\rest_framework\views.py", line 506, in dispatch
    response = handler(request, *args, **kwargs)
               ^^^^^^^^^^^^^^^^^^^^^^^^^^^^^^^^^
  File "E:\New api\newpro\newapp\views.py", line 34, in post
    return JsonResponse({"responseCode":global_msg.UNSUCCESS_RESPONSE_CODE,"response":"Something went Wrong", "error":serializer.errors}, status=status.HTTP_404_NOT_FOUND)
                                       ^^^^^^^^^^^^^^^^^^^^^^^^^^^^^^^^^^
AttributeError: module 'newpro.global_msg' has no attribute 'UNSUCCESS_RESPONSE_CODE'
2023-06-11 20:57:56,808 ERROR "POST /test HTTP/1.1" 500 89790 212 
2023-06-11 20:58:22,750 INFO "GET /test HTTP/1.1" 200 573 212 
2023-06-11 20:59:30,024 INFO E:\New api\newpro\newpro\global_msg.py changed, reloading. 266 
2023-06-11 20:59:31,425 INFO Watching for file changes with StatReloader 668 
2023-06-11 20:59:49,683 WARNING Not Found: /test 241 
2023-06-11 20:59:49,684 WARNING "POST /test HTTP/1.1" 404 125 212 
2023-06-11 21:01:03,701 INFO E:\New api\newpro\newapp\views.py changed, reloading. 266 
2023-06-11 21:01:05,011 INFO Watching for file changes with StatReloader 668 
2023-06-11 21:01:15,566 WARNING Not Found: /test 241 
2023-06-11 21:01:15,567 WARNING "POST /test HTTP/1.1" 404 125 212 
2023-06-11 21:01:26,944 INFO "GET /test HTTP/1.1" 200 573 212 
2023-06-11 22:29:40,339 INFO Watching for file changes with StatReloader 668 
2023-06-11 22:52:43,535 INFO Watching for file changes with StatReloader 668 
2023-06-11 22:54:00,774 INFO E:\New api\newpro\newapp\models.py changed, reloading. 266 
2023-06-11 22:54:02,072 INFO Watching for file changes with StatReloader 668 
2023-06-11 22:54:06,990 INFO E:\New api\newpro\newapp\models.py changed, reloading. 266 
2023-06-11 22:54:08,384 INFO Watching for file changes with StatReloader 668 
2023-06-11 22:54:42,948 INFO E:\New api\newpro\newapp\models.py changed, reloading. 266 
2023-06-11 22:54:44,187 INFO Watching for file changes with StatReloader 668 
2023-06-11 22:55:05,578 INFO E:\New api\newpro\newapp\models.py changed, reloading. 266 
2023-06-11 22:55:06,901 INFO Watching for file changes with StatReloader 668 
2023-06-11 23:07:14,963 INFO Watching for file changes with StatReloader 668 
2023-06-11 23:10:17,700 INFO Watching for file changes with StatReloader 668 
2023-06-11 23:27:18,393 INFO Watching for file changes with StatReloader 668 
2023-06-11 23:33:10,443 INFO Watching for file changes with StatReloader 668 
2023-06-11 23:34:29,707 INFO E:\New api\newpro\newpro\settings.py changed, reloading. 266 
2023-06-11 23:34:30,965 INFO Watching for file changes with StatReloader 668 
